nohup: 忽略输入
INFO:     Will watch for changes in these directories: ['/home/jhyang/AiWeb/webAi_backEnd']
INFO:     Uvicorn running on http://localhost:8888 (Press CTRL+C to quit)
INFO:     Started reloader process [684950] using StatReload
INFO:     Started server process [685016]
INFO:     Waiting for application startup.
INFO:     Application startup complete.
creating table...
[Debug] getting db...
[Debug] getting current user...
INFO:     10.19.48.76:0 - "POST /api/resume/upload HTTP/1.0" 401 Unauthorized
[Debug] getting db...
[Debug] getting current user...
INFO:     10.19.48.76:0 - "POST /api/resume/chat HTTP/1.0" 401 Unauthorized
[Debug] getting db...
[Debug] user login: Admin
INFO:     10.19.48.76:0 - "POST /api/auth/login HTTP/1.0" 200 OK
[Debug] getting db...
[Debug] getting current user...
[Debug] get current user done
[Debug] upload resume...
[Debug] uploadDocuments...
[Debug] upload done {'code': 0, 'data': [{'chunk_method': 'naive', 'created_by': '4eacb51c16bc11f082f456083657867e', 'dataset_id': '02f0f46417b911f09d7a4a54b7ac79ba', 'id': '824524941bef11f0a578a6d00a71041a', 'location': 'resume_e2006a2f-3be7-44f1-8858-53b099baf427.docx', 'name': 'resume_e2006a2f-3be7-44f1-8858-53b099baf427.docx', 'parser_config': {'auto_keywords': 3, 'auto_questions': 1, 'chunk_token_num': 128, 'delimiter': '\\n!?;。；！？', 'graphrag': {'use_graphrag': False}, 'html4excel': False, 'layout_recognize': 'DeepDOC', 'raptor': {'use_raptor': False}}, 'run': 'UNSTART', 'size': 39826, 'thumbnail': '', 'type': 'doc'}]}
[Debug] parseDocuments...
[Debug] parseDocuments done: <Response [200]>
INFO:     10.19.48.76:0 - "POST /api/resume/upload HTTP/1.0" 200 OK
[Debug] getting db...
[Debug] getting current user...
[Debug] get current user done
INFO:     10.19.48.76:0 - "GET /api/resume/newSession HTTP/1.0" 200 OK
[Debug] getting db...
[Debug] getting current user...
[Debug] get current user done
[Debug] chat_resume on session_id: 8ac064da1bef11f08919a6d00a71041a
stream down
INFO:     10.19.48.76:0 - "POST /api/resume/chat HTTP/1.0" 200 OK
[Debug] getting db...
[Debug] user login: Admin
INFO:     10.19.48.76:0 - "POST /api/auth/login HTTP/1.0" 200 OK
[Debug] getting db...
[Debug] getting current user...
[Debug] get current user done
[Debug] chat_resume on session_id: bab86b1a1b7711f0bae5a6d00a71041a
stream down
INFO:     10.19.48.76:0 - "POST /api/resume/chat HTTP/1.0" 200 OK
[Debug] getting db...
[Debug] user login: test_user
INFO:     10.10.182.152:0 - "POST /api/auth/login HTTP/1.0" 401 Unauthorized
[Debug] getting db...
[Debug] user login: Admin
INFO:     10.10.187.95:0 - "POST /api/auth/login HTTP/1.0" 200 OK
[Debug] getting db...
[Debug] user login: Admin
INFO:     10.10.187.95:0 - "POST /api/auth/login HTTP/1.0" 200 OK
[Debug] getting db...
[Debug] user login: Admin
INFO:     10.10.187.95:0 - "POST /api/auth/login HTTP/1.0" 200 OK
[Debug] getting db...
[Debug] user login: Admin
INFO:     10.10.187.95:0 - "POST /api/auth/login HTTP/1.0" 200 OK
[Debug] getting db...
[Debug] user login: Admin
INFO:     10.10.187.95:0 - "POST /api/auth/login HTTP/1.0" 200 OK
[Debug] getting db...
[Debug] user login: Admin
INFO:     10.10.187.95:0 - "POST /api/auth/login HTTP/1.0" 200 OK
[Debug] getting db...
[Debug] user login: Admin
INFO:     10.10.187.95:0 - "POST /api/auth/login HTTP/1.0" 200 OK
[Debug] getting db...
[Debug] user login: Admin
INFO:     10.10.187.95:0 - "POST /api/auth/login HTTP/1.0" 200 OK
[Debug] getting db...
[Debug] user login: test_user
INFO:     10.10.182.152:0 - "POST /api/auth/login HTTP/1.0" 401 Unauthorized
[Debug] getting db...
[Debug] getting current user...
INFO:     10.10.182.152:0 - "GET /api/resume/newSession HTTP/1.0" 401 Unauthorized
[Debug] getting db...
[Debug] user login: Admin
INFO:     10.10.182.152:0 - "POST /api/auth/login HTTP/1.0" 401 Unauthorized
[Debug] getting db...
[Debug] user login: Admin
INFO:     10.10.182.152:0 - "POST /api/auth/login HTTP/1.0" 401 Unauthorized
[Debug] getting db...
[Debug] user login: Admin
INFO:     10.10.182.152:0 - "POST /api/auth/login HTTP/1.0" 200 OK
[Debug] getting db...
[Debug] getting current user...
[Debug] get current user done
INFO:     10.10.182.152:0 - "GET /api/resume/newSession HTTP/1.0" 200 OK
[Debug] getting db...
[Debug] getting current user...
[Debug] get current user done
[Debug] chat_resume on session_id: 2638e89c1c1811f0941ea6d00a71041a
stream down
INFO:     10.10.182.152:0 - "POST /api/resume/chat HTTP/1.0" 200 OK
[Debug] getting db...
[Debug] user login: test_user
INFO:     10.10.182.152:0 - "POST /api/auth/login HTTP/1.0" 401 Unauthorized
[Debug] getting db...
[Debug] user login: Admin
INFO:     10.10.187.95:0 - "POST /api/auth/login HTTP/1.0" 200 OK
[Debug] getting db...
[Debug] user login: Admin
INFO:     10.10.187.95:0 - "POST /api/auth/login HTTP/1.0" 200 OK
[Debug] getting db...
[Debug] user login: Admin
INFO:     10.19.48.76:0 - "POST /api/auth/login HTTP/1.0" 200 OK
[Debug] getting db...
[Debug] getting current user...
[Debug] get current user done
INFO:     10.19.48.76:0 - "GET /api/resume/newSession HTTP/1.0" 200 OK
[Debug] getting db...
[Debug] getting current user...
[Debug] get current user done
[Debug] chat_resume on session_id: b883ebdc1c2911f0b4f2a6d00a71041a
stream down
INFO:     10.19.48.76:0 - "POST /api/resume/chat HTTP/1.0" 200 OK
[Debug] getting db...
[Debug] user login: Admin
INFO:     10.19.48.76:0 - "POST /api/auth/login HTTP/1.0" 200 OK
[Debug] getting db...
[Debug] user login: Admin
INFO:     10.19.48.76:0 - "POST /api/auth/login HTTP/1.0" 200 OK
[Debug] getting db...
[Debug] user login: Admin
INFO:     10.10.182.152:0 - "POST /api/auth/login HTTP/1.0" 200 OK
[Debug] getting db...
[Debug] user login: Admin
INFO:     10.19.48.76:0 - "POST /api/auth/login HTTP/1.0" 200 OK
[Debug] getting db...
[Debug] user login: Admin
INFO:     10.19.48.76:0 - "POST /api/auth/login HTTP/1.0" 200 OK
[Debug] getting db...
[Debug] user login: Admin
INFO:     10.19.48.76:0 - "POST /api/auth/login HTTP/1.0" 200 OK
[Debug] getting db...
[Debug] user login: Admin
INFO:     10.19.48.76:0 - "POST /api/auth/login HTTP/1.0" 200 OK
[Debug] getting db...
[Debug] user login: Admin
INFO:     10.19.48.76:0 - "POST /api/auth/login HTTP/1.0" 200 OK
[Debug] getting db...
[Debug] user login: Admin
INFO:     10.19.48.76:0 - "POST /api/auth/login HTTP/1.0" 200 OK
[Debug] getting db...
[Debug] user login: Admin
INFO:     10.19.48.76:0 - "POST /api/auth/login HTTP/1.0" 200 OK
[Debug] getting db...
[Debug] user login: Admin
INFO:     10.19.48.76:0 - "POST /api/auth/login HTTP/1.0" 200 OK
[Debug] getting db...
[Debug] user login: Admin
INFO:     10.19.48.76:0 - "POST /api/auth/login HTTP/1.0" 200 OK
[Debug] getting db...
[Debug] user login: Admin
INFO:     10.19.48.76:0 - "POST /api/auth/login HTTP/1.0" 200 OK
[Debug] getting db...
[Debug] user login: Admin
INFO:     10.19.48.76:0 - "POST /api/auth/login HTTP/1.0" 200 OK
[Debug] getting db...
[Debug] user login: Admin
INFO:     10.19.48.76:0 - "POST /api/auth/login HTTP/1.0" 200 OK
[Debug] getting db...
[Debug] user login: Admin
INFO:     10.19.48.76:0 - "POST /api/auth/login HTTP/1.0" 200 OK
[Debug] getting db...
[Debug] user login: Admin
INFO:     10.19.48.76:0 - "POST /api/auth/login HTTP/1.0" 200 OK
[Debug] getting db...
[Debug] user login: Admin
INFO:     10.19.48.76:0 - "POST /api/auth/login HTTP/1.0" 200 OK
[Debug] getting db...
[Debug] user login: Admin
INFO:     10.19.48.76:0 - "POST /api/auth/login HTTP/1.0" 200 OK
[Debug] getting db...
[Debug] user login: Admin
INFO:     10.19.48.76:0 - "POST /api/auth/login HTTP/1.0" 200 OK
[Debug] getting db...
[Debug] user login: Admin
INFO:     10.19.48.76:0 - "POST /api/auth/login HTTP/1.0" 200 OK
[Debug] getting db...
[Debug] user login: Admin
INFO:     10.19.48.76:0 - "POST /api/auth/login HTTP/1.0" 200 OK
[Debug] getting db...
[Debug] user login: Admin
INFO:     10.19.48.76:0 - "POST /api/auth/login HTTP/1.0" 200 OK
[Debug] getting db...
[Debug] user login: Admin
INFO:     10.19.48.76:0 - "POST /api/auth/login HTTP/1.0" 200 OK
[Debug] getting db...
[Debug] user login: Admin
INFO:     10.19.48.76:0 - "POST /api/auth/login HTTP/1.0" 200 OK
[Debug] getting db...
[Debug] user login: Admin
INFO:     10.19.48.76:0 - "POST /api/auth/login HTTP/1.0" 200 OK
[Debug] getting db...
[Debug] user login: Admin
INFO:     10.19.48.76:0 - "POST /api/auth/login HTTP/1.0" 200 OK
[Debug] getting db...
[Debug] user login: Admin
INFO:     10.19.98.74:0 - "POST /api/auth/login HTTP/1.0" 200 OK
[Debug] getting db...
[Debug] user login: Admin
INFO:     10.19.48.76:0 - "POST /api/auth/login HTTP/1.0" 200 OK
[Debug] getting db...
[Debug] user login: test_user
INFO:     10.19.98.74:0 - "POST /api/auth/login HTTP/1.0" 401 Unauthorized
[Debug] getting db...
[Debug] user login: Admin
INFO:     10.19.48.76:0 - "POST /api/auth/login HTTP/1.0" 200 OK
[Debug] getting db...
[Debug] user login: Admin
INFO:     10.19.48.76:0 - "POST /api/auth/login HTTP/1.0" 200 OK
[Debug] getting db...
[Debug] user login: Admin
INFO:     10.19.48.76:0 - "POST /api/auth/login HTTP/1.0" 200 OK
[Debug] getting db...
[Debug] user login: Admin
INFO:     10.19.48.76:0 - "POST /api/auth/login HTTP/1.0" 200 OK
[Debug] getting db...
[Debug] user login: Admin
INFO:     10.19.48.76:0 - "POST /api/auth/login HTTP/1.0" 200 OK
[Debug] getting db...
[Debug] user login: Admin
INFO:     10.19.48.76:0 - "POST /api/auth/login HTTP/1.0" 200 OK
[Debug] getting db...
[Debug] user login: Admin
INFO:     10.19.48.76:0 - "POST /api/auth/login HTTP/1.0" 200 OK
[Debug] getting db...
[Debug] user login: Admin
INFO:     10.19.48.76:0 - "POST /api/auth/login HTTP/1.0" 200 OK
[Debug] getting db...
[Debug] user login: Admin
INFO:     10.19.48.76:0 - "POST /api/auth/login HTTP/1.0" 200 OK
[Debug] getting db...
[Debug] user login: Admin
INFO:     10.19.48.76:0 - "POST /api/auth/login HTTP/1.0" 200 OK
[Debug] getting db...
[Debug] user login: Admin
INFO:     10.19.48.76:0 - "POST /api/auth/login HTTP/1.0" 200 OK
[Debug] getting db...
[Debug] user login: Admin
INFO:     10.19.48.76:0 - "POST /api/auth/login HTTP/1.0" 200 OK
[Debug] getting db...
[Debug] user login: Admin
INFO:     10.19.48.76:0 - "POST /api/auth/login HTTP/1.0" 200 OK
[Debug] getting db...
[Debug] user login: Admin
INFO:     10.19.48.76:0 - "POST /api/auth/login HTTP/1.0" 200 OK
[Debug] getting db...
[Debug] user login: Admin
INFO:     10.19.48.76:0 - "POST /api/auth/login HTTP/1.0" 200 OK
[Debug] getting db...
[Debug] user login: Admin
INFO:     10.19.48.76:0 - "POST /api/auth/login HTTP/1.0" 200 OK
[Debug] getting db...
[Debug] user login: Admin
INFO:     10.19.48.76:0 - "POST /api/auth/login HTTP/1.0" 200 OK
[Debug] getting db...
[Debug] user login: Admin
INFO:     10.19.48.76:0 - "POST /api/auth/login HTTP/1.0" 200 OK
[Debug] getting db...
[Debug] user login: Admin
INFO:     10.19.48.76:0 - "POST /api/auth/login HTTP/1.0" 200 OK
[Debug] getting db...
[Debug] user login: Admin
INFO:     10.19.48.76:0 - "POST /api/auth/login HTTP/1.0" 200 OK
[Debug] getting db...
[Debug] user login: Admin
INFO:     10.19.48.76:0 - "POST /api/auth/login HTTP/1.0" 200 OK
[Debug] getting db...
[Debug] user login: Admin
INFO:     10.19.98.74:0 - "POST /api/auth/login HTTP/1.0" 200 OK
[Debug] getting db...
[Debug] user login: Admin
INFO:     10.19.48.76:0 - "POST /api/auth/login HTTP/1.0" 200 OK
[Debug] getting db...
[Debug] user login: Admin
INFO:     10.19.48.76:0 - "POST /api/auth/login HTTP/1.0" 200 OK
[Debug] getting db...
[Debug] user login: Admin
INFO:     10.19.48.76:0 - "POST /api/auth/login HTTP/1.0" 200 OK
[Debug] getting db...
[Debug] user login: Admin
INFO:     10.19.48.76:0 - "POST /api/auth/login HTTP/1.0" 200 OK
[Debug] getting db...
[Debug] user login: Admin
INFO:     10.19.48.76:0 - "POST /api/auth/login HTTP/1.0" 200 OK
[Debug] getting db...
[Debug] user login: Admin
INFO:     10.19.48.76:0 - "POST /api/auth/login HTTP/1.0" 200 OK
[Debug] getting db...
[Debug] user login: Admin
INFO:     10.19.48.76:0 - "POST /api/auth/login HTTP/1.0" 200 OK
[Debug] getting db...
[Debug] user login: Admin
INFO:     10.11.210.54:0 - "POST /api/auth/login HTTP/1.0" 200 OK
[Debug] getting db...
[Debug] user login: Admin
INFO:     10.11.210.54:0 - "POST /api/auth/login HTTP/1.0" 200 OK
[Debug] getting db...
[Debug] user login: test_user
INFO:     10.19.98.74:0 - "POST /api/auth/login HTTP/1.0" 401 Unauthorized
[Debug] getting db...
[Debug] user login: Admin
INFO:     10.19.98.74:0 - "POST /api/auth/login HTTP/1.0" 200 OK
[Debug] getting db...
[Debug] user login: Admin
INFO:     10.19.98.74:0 - "POST /api/auth/login HTTP/1.0" 500 Internal Server Error
ERROR:    Exception in ASGI application
Traceback (most recent call last):
  File "asyncmy/connection.pyx", line 567, in asyncmy.connection.Connection.connect
  File "asyncmy/connection.pyx", line 558, in asyncmy.connection.Connection.connect
  File "/opt/anaconda3/envs/webAi/lib/python3.10/asyncio/tasks.py", line 445, in wait_for
    return fut.result()
  File "/opt/anaconda3/envs/webAi/lib/python3.10/asyncio/streams.py", line 48, in open_connection
    transport, _ = await loop.create_connection(
  File "/opt/anaconda3/envs/webAi/lib/python3.10/asyncio/base_events.py", line 1076, in create_connection
    raise exceptions[0]
  File "/opt/anaconda3/envs/webAi/lib/python3.10/asyncio/base_events.py", line 1060, in create_connection
    sock = await self._connect_sock(
  File "/opt/anaconda3/envs/webAi/lib/python3.10/asyncio/base_events.py", line 969, in _connect_sock
    await self.sock_connect(sock, address)
  File "/opt/anaconda3/envs/webAi/lib/python3.10/asyncio/selector_events.py", line 501, in sock_connect
    return await fut
  File "/opt/anaconda3/envs/webAi/lib/python3.10/asyncio/selector_events.py", line 541, in _sock_connect_cb
    raise OSError(err, f'Connect call failed {address}')
ConnectionRefusedError: [Errno 111] Connect call failed ('127.0.0.1', 3306)

The above exception was the direct cause of the following exception:

Traceback (most recent call last):
  File "/opt/anaconda3/envs/webAi/lib/python3.10/site-packages/sqlalchemy/engine/base.py", line 146, in __init__
    self._dbapi_connection = engine.raw_connection()
  File "/opt/anaconda3/envs/webAi/lib/python3.10/site-packages/sqlalchemy/engine/base.py", line 3298, in raw_connection
    return self.pool.connect()
  File "/opt/anaconda3/envs/webAi/lib/python3.10/site-packages/sqlalchemy/pool/base.py", line 449, in connect
    return _ConnectionFairy._checkout(self)
  File "/opt/anaconda3/envs/webAi/lib/python3.10/site-packages/sqlalchemy/pool/base.py", line 1345, in _checkout
    with util.safe_reraise():
  File "/opt/anaconda3/envs/webAi/lib/python3.10/site-packages/sqlalchemy/util/langhelpers.py", line 146, in __exit__
    raise exc_value.with_traceback(exc_tb)
  File "/opt/anaconda3/envs/webAi/lib/python3.10/site-packages/sqlalchemy/pool/base.py", line 1342, in _checkout
    fairy._connection_record.get_connection()
  File "/opt/anaconda3/envs/webAi/lib/python3.10/site-packages/sqlalchemy/pool/base.py", line 838, in get_connection
    self.__connect()
  File "/opt/anaconda3/envs/webAi/lib/python3.10/site-packages/sqlalchemy/pool/base.py", line 901, in __connect
    with util.safe_reraise():
  File "/opt/anaconda3/envs/webAi/lib/python3.10/site-packages/sqlalchemy/util/langhelpers.py", line 146, in __exit__
    raise exc_value.with_traceback(exc_tb)
  File "/opt/anaconda3/envs/webAi/lib/python3.10/site-packages/sqlalchemy/pool/base.py", line 897, in __connect
    self.dbapi_connection = connection = pool._invoke_creator(self)
  File "/opt/anaconda3/envs/webAi/lib/python3.10/site-packages/sqlalchemy/engine/create.py", line 646, in connect
    return dialect.connect(*cargs, **cparams)
  File "/opt/anaconda3/envs/webAi/lib/python3.10/site-packages/sqlalchemy/engine/default.py", line 625, in connect
    return self.loaded_dbapi.connect(*cargs, **cparams)  # type: ignore[no-any-return]  # NOQA: E501
  File "/opt/anaconda3/envs/webAi/lib/python3.10/site-packages/sqlalchemy/dialects/mysql/asyncmy.py", line 286, in connect
    await_only(creator_fn(*arg, **kw)),
  File "/opt/anaconda3/envs/webAi/lib/python3.10/site-packages/sqlalchemy/util/_concurrency_py3k.py", line 132, in await_only
    return current.parent.switch(awaitable)  # type: ignore[no-any-return,attr-defined] # noqa: E501
  File "/opt/anaconda3/envs/webAi/lib/python3.10/site-packages/sqlalchemy/util/_concurrency_py3k.py", line 196, in greenlet_spawn
    value = await result
  File "asyncmy/connection.pyx", line 1345, in _connect
  File "asyncmy/connection.pyx", line 590, in connect
asyncmy.errors.OperationalError: (2003, "Can't connect to MySQL server on 'localhost' ([Errno 111] Connect call failed ('127.0.0.1', 3306))")

The above exception was the direct cause of the following exception:

Traceback (most recent call last):
  File "/opt/anaconda3/envs/webAi/lib/python3.10/site-packages/uvicorn/protocols/http/h11_impl.py", line 403, in run_asgi
    result = await app(  # type: ignore[func-returns-value]
  File "/opt/anaconda3/envs/webAi/lib/python3.10/site-packages/uvicorn/middleware/proxy_headers.py", line 60, in __call__
    return await self.app(scope, receive, send)
  File "/opt/anaconda3/envs/webAi/lib/python3.10/site-packages/fastapi/applications.py", line 1054, in __call__
    await super().__call__(scope, receive, send)
  File "/opt/anaconda3/envs/webAi/lib/python3.10/site-packages/starlette/applications.py", line 112, in __call__
    await self.middleware_stack(scope, receive, send)
  File "/opt/anaconda3/envs/webAi/lib/python3.10/site-packages/starlette/middleware/errors.py", line 187, in __call__
    raise exc
  File "/opt/anaconda3/envs/webAi/lib/python3.10/site-packages/starlette/middleware/errors.py", line 165, in __call__
    await self.app(scope, receive, _send)
  File "/opt/anaconda3/envs/webAi/lib/python3.10/site-packages/starlette/middleware/cors.py", line 93, in __call__
    await self.simple_response(scope, receive, send, request_headers=headers)
  File "/opt/anaconda3/envs/webAi/lib/python3.10/site-packages/starlette/middleware/cors.py", line 144, in simple_response
    await self.app(scope, receive, send)
  File "/opt/anaconda3/envs/webAi/lib/python3.10/site-packages/starlette/middleware/base.py", line 173, in __call__
    with recv_stream, send_stream, collapse_excgroups():
  File "/opt/anaconda3/envs/webAi/lib/python3.10/contextlib.py", line 153, in __exit__
    self.gen.throw(typ, value, traceback)
  File "/opt/anaconda3/envs/webAi/lib/python3.10/site-packages/starlette/_utils.py", line 82, in collapse_excgroups
    raise exc
  File "/opt/anaconda3/envs/webAi/lib/python3.10/site-packages/starlette/middleware/base.py", line 175, in __call__
    response = await self.dispatch_func(request, call_next)
  File "/home/jhyang/AiWeb/webAi_backEnd/app/main.py", line 20, in add_process_time_header
    response = await call_next(request)
  File "/opt/anaconda3/envs/webAi/lib/python3.10/site-packages/starlette/middleware/base.py", line 153, in call_next
    raise app_exc
  File "/opt/anaconda3/envs/webAi/lib/python3.10/site-packages/starlette/middleware/base.py", line 140, in coro
    await self.app(scope, receive_or_disconnect, send_no_error)
  File "/opt/anaconda3/envs/webAi/lib/python3.10/site-packages/starlette/middleware/exceptions.py", line 62, in __call__
    await wrap_app_handling_exceptions(self.app, conn)(scope, receive, send)
  File "/opt/anaconda3/envs/webAi/lib/python3.10/site-packages/starlette/_exception_handler.py", line 53, in wrapped_app
    raise exc
  File "/opt/anaconda3/envs/webAi/lib/python3.10/site-packages/starlette/_exception_handler.py", line 42, in wrapped_app
    await app(scope, receive, sender)
  File "/opt/anaconda3/envs/webAi/lib/python3.10/site-packages/starlette/routing.py", line 714, in __call__
    await self.middleware_stack(scope, receive, send)
  File "/opt/anaconda3/envs/webAi/lib/python3.10/site-packages/starlette/routing.py", line 734, in app
    await route.handle(scope, receive, send)
  File "/opt/anaconda3/envs/webAi/lib/python3.10/site-packages/starlette/routing.py", line 288, in handle
    await self.app(scope, receive, send)
  File "/opt/anaconda3/envs/webAi/lib/python3.10/site-packages/starlette/routing.py", line 76, in app
    await wrap_app_handling_exceptions(app, request)(scope, receive, send)
  File "/opt/anaconda3/envs/webAi/lib/python3.10/site-packages/starlette/_exception_handler.py", line 53, in wrapped_app
    raise exc
  File "/opt/anaconda3/envs/webAi/lib/python3.10/site-packages/starlette/_exception_handler.py", line 42, in wrapped_app
    await app(scope, receive, sender)
  File "/opt/anaconda3/envs/webAi/lib/python3.10/site-packages/starlette/routing.py", line 73, in app
    response = await f(request)
  File "/opt/anaconda3/envs/webAi/lib/python3.10/site-packages/fastapi/routing.py", line 301, in app
    raw_response = await run_endpoint_function(
  File "/opt/anaconda3/envs/webAi/lib/python3.10/site-packages/fastapi/routing.py", line 212, in run_endpoint_function
    return await dependant.call(**values)
  File "/home/jhyang/AiWeb/webAi_backEnd/app/routers/auth.py", line 83, in login
    result = await db.execute(
  File "/opt/anaconda3/envs/webAi/lib/python3.10/site-packages/sqlalchemy/ext/asyncio/session.py", line 463, in execute
    result = await greenlet_spawn(
  File "/opt/anaconda3/envs/webAi/lib/python3.10/site-packages/sqlalchemy/util/_concurrency_py3k.py", line 201, in greenlet_spawn
    result = context.throw(*sys.exc_info())
  File "/opt/anaconda3/envs/webAi/lib/python3.10/site-packages/sqlalchemy/orm/session.py", line 2365, in execute
    return self._execute_internal(
  File "/opt/anaconda3/envs/webAi/lib/python3.10/site-packages/sqlalchemy/orm/session.py", line 2241, in _execute_internal
    conn = self._connection_for_bind(bind)
  File "/opt/anaconda3/envs/webAi/lib/python3.10/site-packages/sqlalchemy/orm/session.py", line 2110, in _connection_for_bind
    return trans._connection_for_bind(engine, execution_options)
  File "<string>", line 2, in _connection_for_bind
  File "/opt/anaconda3/envs/webAi/lib/python3.10/site-packages/sqlalchemy/orm/state_changes.py", line 139, in _go
    ret_value = fn(self, *arg, **kw)
  File "/opt/anaconda3/envs/webAi/lib/python3.10/site-packages/sqlalchemy/orm/session.py", line 1189, in _connection_for_bind
    conn = bind.connect()
  File "/opt/anaconda3/envs/webAi/lib/python3.10/site-packages/sqlalchemy/engine/base.py", line 3274, in connect
    return self._connection_cls(self)
  File "/opt/anaconda3/envs/webAi/lib/python3.10/site-packages/sqlalchemy/engine/base.py", line 148, in __init__
    Connection._handle_dbapi_exception_noconnection(
  File "/opt/anaconda3/envs/webAi/lib/python3.10/site-packages/sqlalchemy/engine/base.py", line 2439, in _handle_dbapi_exception_noconnection
    raise sqlalchemy_exception.with_traceback(exc_info[2]) from e
  File "/opt/anaconda3/envs/webAi/lib/python3.10/site-packages/sqlalchemy/engine/base.py", line 146, in __init__
    self._dbapi_connection = engine.raw_connection()
  File "/opt/anaconda3/envs/webAi/lib/python3.10/site-packages/sqlalchemy/engine/base.py", line 3298, in raw_connection
    return self.pool.connect()
  File "/opt/anaconda3/envs/webAi/lib/python3.10/site-packages/sqlalchemy/pool/base.py", line 449, in connect
    return _ConnectionFairy._checkout(self)
  File "/opt/anaconda3/envs/webAi/lib/python3.10/site-packages/sqlalchemy/pool/base.py", line 1345, in _checkout
    with util.safe_reraise():
  File "/opt/anaconda3/envs/webAi/lib/python3.10/site-packages/sqlalchemy/util/langhelpers.py", line 146, in __exit__
    raise exc_value.with_traceback(exc_tb)
  File "/opt/anaconda3/envs/webAi/lib/python3.10/site-packages/sqlalchemy/pool/base.py", line 1342, in _checkout
    fairy._connection_record.get_connection()
  File "/opt/anaconda3/envs/webAi/lib/python3.10/site-packages/sqlalchemy/pool/base.py", line 838, in get_connection
    self.__connect()
  File "/opt/anaconda3/envs/webAi/lib/python3.10/site-packages/sqlalchemy/pool/base.py", line 901, in __connect
    with util.safe_reraise():
  File "/opt/anaconda3/envs/webAi/lib/python3.10/site-packages/sqlalchemy/util/langhelpers.py", line 146, in __exit__
    raise exc_value.with_traceback(exc_tb)
  File "/opt/anaconda3/envs/webAi/lib/python3.10/site-packages/sqlalchemy/pool/base.py", line 897, in __connect
    self.dbapi_connection = connection = pool._invoke_creator(self)
  File "/opt/anaconda3/envs/webAi/lib/python3.10/site-packages/sqlalchemy/engine/create.py", line 646, in connect
    return dialect.connect(*cargs, **cparams)
  File "/opt/anaconda3/envs/webAi/lib/python3.10/site-packages/sqlalchemy/engine/default.py", line 625, in connect
    return self.loaded_dbapi.connect(*cargs, **cparams)  # type: ignore[no-any-return]  # NOQA: E501
  File "/opt/anaconda3/envs/webAi/lib/python3.10/site-packages/sqlalchemy/dialects/mysql/asyncmy.py", line 286, in connect
    await_only(creator_fn(*arg, **kw)),
  File "/opt/anaconda3/envs/webAi/lib/python3.10/site-packages/sqlalchemy/util/_concurrency_py3k.py", line 132, in await_only
    return current.parent.switch(awaitable)  # type: ignore[no-any-return,attr-defined] # noqa: E501
  File "/opt/anaconda3/envs/webAi/lib/python3.10/site-packages/sqlalchemy/util/_concurrency_py3k.py", line 196, in greenlet_spawn
    value = await result
  File "asyncmy/connection.pyx", line 1345, in _connect
  File "asyncmy/connection.pyx", line 590, in connect
sqlalchemy.exc.OperationalError: (asyncmy.errors.OperationalError) (2003, "Can't connect to MySQL server on 'localhost' ([Errno 111] Connect call failed ('127.0.0.1', 3306))")
(Background on this error at: https://sqlalche.me/e/20/e3q8)
[Debug] getting db...
[Debug] user login: test_user
INFO:     10.19.98.74:0 - "POST /api/auth/login HTTP/1.0" 500 Internal Server Error
ERROR:    Exception in ASGI application
Traceback (most recent call last):
  File "asyncmy/connection.pyx", line 567, in asyncmy.connection.Connection.connect
  File "asyncmy/connection.pyx", line 558, in asyncmy.connection.Connection.connect
  File "/opt/anaconda3/envs/webAi/lib/python3.10/asyncio/tasks.py", line 445, in wait_for
    return fut.result()
  File "/opt/anaconda3/envs/webAi/lib/python3.10/asyncio/streams.py", line 48, in open_connection
    transport, _ = await loop.create_connection(
  File "/opt/anaconda3/envs/webAi/lib/python3.10/asyncio/base_events.py", line 1076, in create_connection
    raise exceptions[0]
  File "/opt/anaconda3/envs/webAi/lib/python3.10/asyncio/base_events.py", line 1060, in create_connection
    sock = await self._connect_sock(
  File "/opt/anaconda3/envs/webAi/lib/python3.10/asyncio/base_events.py", line 969, in _connect_sock
    await self.sock_connect(sock, address)
  File "/opt/anaconda3/envs/webAi/lib/python3.10/asyncio/selector_events.py", line 501, in sock_connect
    return await fut
  File "/opt/anaconda3/envs/webAi/lib/python3.10/asyncio/selector_events.py", line 541, in _sock_connect_cb
    raise OSError(err, f'Connect call failed {address}')
ConnectionRefusedError: [Errno 111] Connect call failed ('127.0.0.1', 3306)

The above exception was the direct cause of the following exception:

Traceback (most recent call last):
  File "/opt/anaconda3/envs/webAi/lib/python3.10/site-packages/sqlalchemy/engine/base.py", line 146, in __init__
    self._dbapi_connection = engine.raw_connection()
  File "/opt/anaconda3/envs/webAi/lib/python3.10/site-packages/sqlalchemy/engine/base.py", line 3298, in raw_connection
    return self.pool.connect()
  File "/opt/anaconda3/envs/webAi/lib/python3.10/site-packages/sqlalchemy/pool/base.py", line 449, in connect
    return _ConnectionFairy._checkout(self)
  File "/opt/anaconda3/envs/webAi/lib/python3.10/site-packages/sqlalchemy/pool/base.py", line 1264, in _checkout
    fairy = _ConnectionRecord.checkout(pool)
  File "/opt/anaconda3/envs/webAi/lib/python3.10/site-packages/sqlalchemy/pool/base.py", line 718, in checkout
    with util.safe_reraise():
  File "/opt/anaconda3/envs/webAi/lib/python3.10/site-packages/sqlalchemy/util/langhelpers.py", line 146, in __exit__
    raise exc_value.with_traceback(exc_tb)
  File "/opt/anaconda3/envs/webAi/lib/python3.10/site-packages/sqlalchemy/pool/base.py", line 716, in checkout
    dbapi_connection = rec.get_connection()
  File "/opt/anaconda3/envs/webAi/lib/python3.10/site-packages/sqlalchemy/pool/base.py", line 838, in get_connection
    self.__connect()
  File "/opt/anaconda3/envs/webAi/lib/python3.10/site-packages/sqlalchemy/pool/base.py", line 901, in __connect
    with util.safe_reraise():
  File "/opt/anaconda3/envs/webAi/lib/python3.10/site-packages/sqlalchemy/util/langhelpers.py", line 146, in __exit__
    raise exc_value.with_traceback(exc_tb)
  File "/opt/anaconda3/envs/webAi/lib/python3.10/site-packages/sqlalchemy/pool/base.py", line 897, in __connect
    self.dbapi_connection = connection = pool._invoke_creator(self)
  File "/opt/anaconda3/envs/webAi/lib/python3.10/site-packages/sqlalchemy/engine/create.py", line 646, in connect
    return dialect.connect(*cargs, **cparams)
  File "/opt/anaconda3/envs/webAi/lib/python3.10/site-packages/sqlalchemy/engine/default.py", line 625, in connect
    return self.loaded_dbapi.connect(*cargs, **cparams)  # type: ignore[no-any-return]  # NOQA: E501
  File "/opt/anaconda3/envs/webAi/lib/python3.10/site-packages/sqlalchemy/dialects/mysql/asyncmy.py", line 286, in connect
    await_only(creator_fn(*arg, **kw)),
  File "/opt/anaconda3/envs/webAi/lib/python3.10/site-packages/sqlalchemy/util/_concurrency_py3k.py", line 132, in await_only
    return current.parent.switch(awaitable)  # type: ignore[no-any-return,attr-defined] # noqa: E501
  File "/opt/anaconda3/envs/webAi/lib/python3.10/site-packages/sqlalchemy/util/_concurrency_py3k.py", line 196, in greenlet_spawn
    value = await result
  File "asyncmy/connection.pyx", line 1345, in _connect
  File "asyncmy/connection.pyx", line 590, in connect
asyncmy.errors.OperationalError: (2003, "Can't connect to MySQL server on 'localhost' ([Errno 111] Connect call failed ('127.0.0.1', 3306))")

The above exception was the direct cause of the following exception:

Traceback (most recent call last):
  File "/opt/anaconda3/envs/webAi/lib/python3.10/site-packages/uvicorn/protocols/http/h11_impl.py", line 403, in run_asgi
    result = await app(  # type: ignore[func-returns-value]
  File "/opt/anaconda3/envs/webAi/lib/python3.10/site-packages/uvicorn/middleware/proxy_headers.py", line 60, in __call__
    return await self.app(scope, receive, send)
  File "/opt/anaconda3/envs/webAi/lib/python3.10/site-packages/fastapi/applications.py", line 1054, in __call__
    await super().__call__(scope, receive, send)
  File "/opt/anaconda3/envs/webAi/lib/python3.10/site-packages/starlette/applications.py", line 112, in __call__
    await self.middleware_stack(scope, receive, send)
  File "/opt/anaconda3/envs/webAi/lib/python3.10/site-packages/starlette/middleware/errors.py", line 187, in __call__
    raise exc
  File "/opt/anaconda3/envs/webAi/lib/python3.10/site-packages/starlette/middleware/errors.py", line 165, in __call__
    await self.app(scope, receive, _send)
  File "/opt/anaconda3/envs/webAi/lib/python3.10/site-packages/starlette/middleware/cors.py", line 93, in __call__
    await self.simple_response(scope, receive, send, request_headers=headers)
  File "/opt/anaconda3/envs/webAi/lib/python3.10/site-packages/starlette/middleware/cors.py", line 144, in simple_response
    await self.app(scope, receive, send)
  File "/opt/anaconda3/envs/webAi/lib/python3.10/site-packages/starlette/middleware/base.py", line 173, in __call__
    with recv_stream, send_stream, collapse_excgroups():
  File "/opt/anaconda3/envs/webAi/lib/python3.10/contextlib.py", line 153, in __exit__
    self.gen.throw(typ, value, traceback)
  File "/opt/anaconda3/envs/webAi/lib/python3.10/site-packages/starlette/_utils.py", line 82, in collapse_excgroups
    raise exc
  File "/opt/anaconda3/envs/webAi/lib/python3.10/site-packages/starlette/middleware/base.py", line 175, in __call__
    response = await self.dispatch_func(request, call_next)
  File "/home/jhyang/AiWeb/webAi_backEnd/app/main.py", line 20, in add_process_time_header
    response = await call_next(request)
  File "/opt/anaconda3/envs/webAi/lib/python3.10/site-packages/starlette/middleware/base.py", line 153, in call_next
    raise app_exc
  File "/opt/anaconda3/envs/webAi/lib/python3.10/site-packages/starlette/middleware/base.py", line 140, in coro
    await self.app(scope, receive_or_disconnect, send_no_error)
  File "/opt/anaconda3/envs/webAi/lib/python3.10/site-packages/starlette/middleware/exceptions.py", line 62, in __call__
    await wrap_app_handling_exceptions(self.app, conn)(scope, receive, send)
  File "/opt/anaconda3/envs/webAi/lib/python3.10/site-packages/starlette/_exception_handler.py", line 53, in wrapped_app
    raise exc
  File "/opt/anaconda3/envs/webAi/lib/python3.10/site-packages/starlette/_exception_handler.py", line 42, in wrapped_app
    await app(scope, receive, sender)
  File "/opt/anaconda3/envs/webAi/lib/python3.10/site-packages/starlette/routing.py", line 714, in __call__
    await self.middleware_stack(scope, receive, send)
  File "/opt/anaconda3/envs/webAi/lib/python3.10/site-packages/starlette/routing.py", line 734, in app
    await route.handle(scope, receive, send)
  File "/opt/anaconda3/envs/webAi/lib/python3.10/site-packages/starlette/routing.py", line 288, in handle
    await self.app(scope, receive, send)
  File "/opt/anaconda3/envs/webAi/lib/python3.10/site-packages/starlette/routing.py", line 76, in app
    await wrap_app_handling_exceptions(app, request)(scope, receive, send)
  File "/opt/anaconda3/envs/webAi/lib/python3.10/site-packages/starlette/_exception_handler.py", line 53, in wrapped_app
    raise exc
  File "/opt/anaconda3/envs/webAi/lib/python3.10/site-packages/starlette/_exception_handler.py", line 42, in wrapped_app
    await app(scope, receive, sender)
  File "/opt/anaconda3/envs/webAi/lib/python3.10/site-packages/starlette/routing.py", line 73, in app
    response = await f(request)
  File "/opt/anaconda3/envs/webAi/lib/python3.10/site-packages/fastapi/routing.py", line 301, in app
    raw_response = await run_endpoint_function(
  File "/opt/anaconda3/envs/webAi/lib/python3.10/site-packages/fastapi/routing.py", line 212, in run_endpoint_function
    return await dependant.call(**values)
  File "/home/jhyang/AiWeb/webAi_backEnd/app/routers/auth.py", line 83, in login
    result = await db.execute(
  File "/opt/anaconda3/envs/webAi/lib/python3.10/site-packages/sqlalchemy/ext/asyncio/session.py", line 463, in execute
    result = await greenlet_spawn(
  File "/opt/anaconda3/envs/webAi/lib/python3.10/site-packages/sqlalchemy/util/_concurrency_py3k.py", line 201, in greenlet_spawn
    result = context.throw(*sys.exc_info())
  File "/opt/anaconda3/envs/webAi/lib/python3.10/site-packages/sqlalchemy/orm/session.py", line 2365, in execute
    return self._execute_internal(
  File "/opt/anaconda3/envs/webAi/lib/python3.10/site-packages/sqlalchemy/orm/session.py", line 2241, in _execute_internal
    conn = self._connection_for_bind(bind)
  File "/opt/anaconda3/envs/webAi/lib/python3.10/site-packages/sqlalchemy/orm/session.py", line 2110, in _connection_for_bind
    return trans._connection_for_bind(engine, execution_options)
  File "<string>", line 2, in _connection_for_bind
  File "/opt/anaconda3/envs/webAi/lib/python3.10/site-packages/sqlalchemy/orm/state_changes.py", line 139, in _go
    ret_value = fn(self, *arg, **kw)
  File "/opt/anaconda3/envs/webAi/lib/python3.10/site-packages/sqlalchemy/orm/session.py", line 1189, in _connection_for_bind
    conn = bind.connect()
  File "/opt/anaconda3/envs/webAi/lib/python3.10/site-packages/sqlalchemy/engine/base.py", line 3274, in connect
    return self._connection_cls(self)
  File "/opt/anaconda3/envs/webAi/lib/python3.10/site-packages/sqlalchemy/engine/base.py", line 148, in __init__
    Connection._handle_dbapi_exception_noconnection(
  File "/opt/anaconda3/envs/webAi/lib/python3.10/site-packages/sqlalchemy/engine/base.py", line 2439, in _handle_dbapi_exception_noconnection
    raise sqlalchemy_exception.with_traceback(exc_info[2]) from e
  File "/opt/anaconda3/envs/webAi/lib/python3.10/site-packages/sqlalchemy/engine/base.py", line 146, in __init__
    self._dbapi_connection = engine.raw_connection()
  File "/opt/anaconda3/envs/webAi/lib/python3.10/site-packages/sqlalchemy/engine/base.py", line 3298, in raw_connection
    return self.pool.connect()
  File "/opt/anaconda3/envs/webAi/lib/python3.10/site-packages/sqlalchemy/pool/base.py", line 449, in connect
    return _ConnectionFairy._checkout(self)
  File "/opt/anaconda3/envs/webAi/lib/python3.10/site-packages/sqlalchemy/pool/base.py", line 1264, in _checkout
    fairy = _ConnectionRecord.checkout(pool)
  File "/opt/anaconda3/envs/webAi/lib/python3.10/site-packages/sqlalchemy/pool/base.py", line 718, in checkout
    with util.safe_reraise():
  File "/opt/anaconda3/envs/webAi/lib/python3.10/site-packages/sqlalchemy/util/langhelpers.py", line 146, in __exit__
    raise exc_value.with_traceback(exc_tb)
  File "/opt/anaconda3/envs/webAi/lib/python3.10/site-packages/sqlalchemy/pool/base.py", line 716, in checkout
    dbapi_connection = rec.get_connection()
  File "/opt/anaconda3/envs/webAi/lib/python3.10/site-packages/sqlalchemy/pool/base.py", line 838, in get_connection
    self.__connect()
  File "/opt/anaconda3/envs/webAi/lib/python3.10/site-packages/sqlalchemy/pool/base.py", line 901, in __connect
    with util.safe_reraise():
  File "/opt/anaconda3/envs/webAi/lib/python3.10/site-packages/sqlalchemy/util/langhelpers.py", line 146, in __exit__
    raise exc_value.with_traceback(exc_tb)
  File "/opt/anaconda3/envs/webAi/lib/python3.10/site-packages/sqlalchemy/pool/base.py", line 897, in __connect
    self.dbapi_connection = connection = pool._invoke_creator(self)
  File "/opt/anaconda3/envs/webAi/lib/python3.10/site-packages/sqlalchemy/engine/create.py", line 646, in connect
    return dialect.connect(*cargs, **cparams)
  File "/opt/anaconda3/envs/webAi/lib/python3.10/site-packages/sqlalchemy/engine/default.py", line 625, in connect
    return self.loaded_dbapi.connect(*cargs, **cparams)  # type: ignore[no-any-return]  # NOQA: E501
  File "/opt/anaconda3/envs/webAi/lib/python3.10/site-packages/sqlalchemy/dialects/mysql/asyncmy.py", line 286, in connect
    await_only(creator_fn(*arg, **kw)),
  File "/opt/anaconda3/envs/webAi/lib/python3.10/site-packages/sqlalchemy/util/_concurrency_py3k.py", line 132, in await_only
    return current.parent.switch(awaitable)  # type: ignore[no-any-return,attr-defined] # noqa: E501
  File "/opt/anaconda3/envs/webAi/lib/python3.10/site-packages/sqlalchemy/util/_concurrency_py3k.py", line 196, in greenlet_spawn
    value = await result
  File "asyncmy/connection.pyx", line 1345, in _connect
  File "asyncmy/connection.pyx", line 590, in connect
sqlalchemy.exc.OperationalError: (asyncmy.errors.OperationalError) (2003, "Can't connect to MySQL server on 'localhost' ([Errno 111] Connect call failed ('127.0.0.1', 3306))")
(Background on this error at: https://sqlalche.me/e/20/e3q8)
[Debug] getting db...
[Debug] user login: Admin
INFO:     10.19.98.74:0 - "POST /api/auth/login HTTP/1.0" 500 Internal Server Error
ERROR:    Exception in ASGI application
Traceback (most recent call last):
  File "asyncmy/connection.pyx", line 567, in asyncmy.connection.Connection.connect
  File "asyncmy/connection.pyx", line 558, in asyncmy.connection.Connection.connect
  File "/opt/anaconda3/envs/webAi/lib/python3.10/asyncio/tasks.py", line 445, in wait_for
    return fut.result()
  File "/opt/anaconda3/envs/webAi/lib/python3.10/asyncio/streams.py", line 48, in open_connection
    transport, _ = await loop.create_connection(
  File "/opt/anaconda3/envs/webAi/lib/python3.10/asyncio/base_events.py", line 1076, in create_connection
    raise exceptions[0]
  File "/opt/anaconda3/envs/webAi/lib/python3.10/asyncio/base_events.py", line 1060, in create_connection
    sock = await self._connect_sock(
  File "/opt/anaconda3/envs/webAi/lib/python3.10/asyncio/base_events.py", line 969, in _connect_sock
    await self.sock_connect(sock, address)
  File "/opt/anaconda3/envs/webAi/lib/python3.10/asyncio/selector_events.py", line 501, in sock_connect
    return await fut
  File "/opt/anaconda3/envs/webAi/lib/python3.10/asyncio/selector_events.py", line 541, in _sock_connect_cb
    raise OSError(err, f'Connect call failed {address}')
ConnectionRefusedError: [Errno 111] Connect call failed ('127.0.0.1', 3306)

The above exception was the direct cause of the following exception:

Traceback (most recent call last):
  File "/opt/anaconda3/envs/webAi/lib/python3.10/site-packages/sqlalchemy/engine/base.py", line 146, in __init__
    self._dbapi_connection = engine.raw_connection()
  File "/opt/anaconda3/envs/webAi/lib/python3.10/site-packages/sqlalchemy/engine/base.py", line 3298, in raw_connection
    return self.pool.connect()
  File "/opt/anaconda3/envs/webAi/lib/python3.10/site-packages/sqlalchemy/pool/base.py", line 449, in connect
    return _ConnectionFairy._checkout(self)
  File "/opt/anaconda3/envs/webAi/lib/python3.10/site-packages/sqlalchemy/pool/base.py", line 1264, in _checkout
    fairy = _ConnectionRecord.checkout(pool)
  File "/opt/anaconda3/envs/webAi/lib/python3.10/site-packages/sqlalchemy/pool/base.py", line 718, in checkout
    with util.safe_reraise():
  File "/opt/anaconda3/envs/webAi/lib/python3.10/site-packages/sqlalchemy/util/langhelpers.py", line 146, in __exit__
    raise exc_value.with_traceback(exc_tb)
  File "/opt/anaconda3/envs/webAi/lib/python3.10/site-packages/sqlalchemy/pool/base.py", line 716, in checkout
    dbapi_connection = rec.get_connection()
  File "/opt/anaconda3/envs/webAi/lib/python3.10/site-packages/sqlalchemy/pool/base.py", line 838, in get_connection
    self.__connect()
  File "/opt/anaconda3/envs/webAi/lib/python3.10/site-packages/sqlalchemy/pool/base.py", line 901, in __connect
    with util.safe_reraise():
  File "/opt/anaconda3/envs/webAi/lib/python3.10/site-packages/sqlalchemy/util/langhelpers.py", line 146, in __exit__
    raise exc_value.with_traceback(exc_tb)
  File "/opt/anaconda3/envs/webAi/lib/python3.10/site-packages/sqlalchemy/pool/base.py", line 897, in __connect
    self.dbapi_connection = connection = pool._invoke_creator(self)
  File "/opt/anaconda3/envs/webAi/lib/python3.10/site-packages/sqlalchemy/engine/create.py", line 646, in connect
    return dialect.connect(*cargs, **cparams)
  File "/opt/anaconda3/envs/webAi/lib/python3.10/site-packages/sqlalchemy/engine/default.py", line 625, in connect
    return self.loaded_dbapi.connect(*cargs, **cparams)  # type: ignore[no-any-return]  # NOQA: E501
  File "/opt/anaconda3/envs/webAi/lib/python3.10/site-packages/sqlalchemy/dialects/mysql/asyncmy.py", line 286, in connect
    await_only(creator_fn(*arg, **kw)),
  File "/opt/anaconda3/envs/webAi/lib/python3.10/site-packages/sqlalchemy/util/_concurrency_py3k.py", line 132, in await_only
    return current.parent.switch(awaitable)  # type: ignore[no-any-return,attr-defined] # noqa: E501
  File "/opt/anaconda3/envs/webAi/lib/python3.10/site-packages/sqlalchemy/util/_concurrency_py3k.py", line 196, in greenlet_spawn
    value = await result
  File "asyncmy/connection.pyx", line 1345, in _connect
  File "asyncmy/connection.pyx", line 590, in connect
asyncmy.errors.OperationalError: (2003, "Can't connect to MySQL server on 'localhost' ([Errno 111] Connect call failed ('127.0.0.1', 3306))")

The above exception was the direct cause of the following exception:

Traceback (most recent call last):
  File "/opt/anaconda3/envs/webAi/lib/python3.10/site-packages/uvicorn/protocols/http/h11_impl.py", line 403, in run_asgi
    result = await app(  # type: ignore[func-returns-value]
  File "/opt/anaconda3/envs/webAi/lib/python3.10/site-packages/uvicorn/middleware/proxy_headers.py", line 60, in __call__
    return await self.app(scope, receive, send)
  File "/opt/anaconda3/envs/webAi/lib/python3.10/site-packages/fastapi/applications.py", line 1054, in __call__
    await super().__call__(scope, receive, send)
  File "/opt/anaconda3/envs/webAi/lib/python3.10/site-packages/starlette/applications.py", line 112, in __call__
    await self.middleware_stack(scope, receive, send)
  File "/opt/anaconda3/envs/webAi/lib/python3.10/site-packages/starlette/middleware/errors.py", line 187, in __call__
    raise exc
  File "/opt/anaconda3/envs/webAi/lib/python3.10/site-packages/starlette/middleware/errors.py", line 165, in __call__
    await self.app(scope, receive, _send)
  File "/opt/anaconda3/envs/webAi/lib/python3.10/site-packages/starlette/middleware/cors.py", line 93, in __call__
    await self.simple_response(scope, receive, send, request_headers=headers)
  File "/opt/anaconda3/envs/webAi/lib/python3.10/site-packages/starlette/middleware/cors.py", line 144, in simple_response
    await self.app(scope, receive, send)
  File "/opt/anaconda3/envs/webAi/lib/python3.10/site-packages/starlette/middleware/base.py", line 173, in __call__
    with recv_stream, send_stream, collapse_excgroups():
  File "/opt/anaconda3/envs/webAi/lib/python3.10/contextlib.py", line 153, in __exit__
    self.gen.throw(typ, value, traceback)
  File "/opt/anaconda3/envs/webAi/lib/python3.10/site-packages/starlette/_utils.py", line 82, in collapse_excgroups
    raise exc
  File "/opt/anaconda3/envs/webAi/lib/python3.10/site-packages/starlette/middleware/base.py", line 175, in __call__
    response = await self.dispatch_func(request, call_next)
  File "/home/jhyang/AiWeb/webAi_backEnd/app/main.py", line 20, in add_process_time_header
    response = await call_next(request)
  File "/opt/anaconda3/envs/webAi/lib/python3.10/site-packages/starlette/middleware/base.py", line 153, in call_next
    raise app_exc
  File "/opt/anaconda3/envs/webAi/lib/python3.10/site-packages/starlette/middleware/base.py", line 140, in coro
    await self.app(scope, receive_or_disconnect, send_no_error)
  File "/opt/anaconda3/envs/webAi/lib/python3.10/site-packages/starlette/middleware/exceptions.py", line 62, in __call__
    await wrap_app_handling_exceptions(self.app, conn)(scope, receive, send)
  File "/opt/anaconda3/envs/webAi/lib/python3.10/site-packages/starlette/_exception_handler.py", line 53, in wrapped_app
    raise exc
  File "/opt/anaconda3/envs/webAi/lib/python3.10/site-packages/starlette/_exception_handler.py", line 42, in wrapped_app
    await app(scope, receive, sender)
  File "/opt/anaconda3/envs/webAi/lib/python3.10/site-packages/starlette/routing.py", line 714, in __call__
    await self.middleware_stack(scope, receive, send)
  File "/opt/anaconda3/envs/webAi/lib/python3.10/site-packages/starlette/routing.py", line 734, in app
    await route.handle(scope, receive, send)
  File "/opt/anaconda3/envs/webAi/lib/python3.10/site-packages/starlette/routing.py", line 288, in handle
    await self.app(scope, receive, send)
  File "/opt/anaconda3/envs/webAi/lib/python3.10/site-packages/starlette/routing.py", line 76, in app
    await wrap_app_handling_exceptions(app, request)(scope, receive, send)
  File "/opt/anaconda3/envs/webAi/lib/python3.10/site-packages/starlette/_exception_handler.py", line 53, in wrapped_app
    raise exc
  File "/opt/anaconda3/envs/webAi/lib/python3.10/site-packages/starlette/_exception_handler.py", line 42, in wrapped_app
    await app(scope, receive, sender)
  File "/opt/anaconda3/envs/webAi/lib/python3.10/site-packages/starlette/routing.py", line 73, in app
    response = await f(request)
  File "/opt/anaconda3/envs/webAi/lib/python3.10/site-packages/fastapi/routing.py", line 301, in app
    raw_response = await run_endpoint_function(
  File "/opt/anaconda3/envs/webAi/lib/python3.10/site-packages/fastapi/routing.py", line 212, in run_endpoint_function
    return await dependant.call(**values)
  File "/home/jhyang/AiWeb/webAi_backEnd/app/routers/auth.py", line 83, in login
    result = await db.execute(
  File "/opt/anaconda3/envs/webAi/lib/python3.10/site-packages/sqlalchemy/ext/asyncio/session.py", line 463, in execute
    result = await greenlet_spawn(
  File "/opt/anaconda3/envs/webAi/lib/python3.10/site-packages/sqlalchemy/util/_concurrency_py3k.py", line 201, in greenlet_spawn
    result = context.throw(*sys.exc_info())
  File "/opt/anaconda3/envs/webAi/lib/python3.10/site-packages/sqlalchemy/orm/session.py", line 2365, in execute
    return self._execute_internal(
  File "/opt/anaconda3/envs/webAi/lib/python3.10/site-packages/sqlalchemy/orm/session.py", line 2241, in _execute_internal
    conn = self._connection_for_bind(bind)
  File "/opt/anaconda3/envs/webAi/lib/python3.10/site-packages/sqlalchemy/orm/session.py", line 2110, in _connection_for_bind
    return trans._connection_for_bind(engine, execution_options)
  File "<string>", line 2, in _connection_for_bind
  File "/opt/anaconda3/envs/webAi/lib/python3.10/site-packages/sqlalchemy/orm/state_changes.py", line 139, in _go
    ret_value = fn(self, *arg, **kw)
  File "/opt/anaconda3/envs/webAi/lib/python3.10/site-packages/sqlalchemy/orm/session.py", line 1189, in _connection_for_bind
    conn = bind.connect()
  File "/opt/anaconda3/envs/webAi/lib/python3.10/site-packages/sqlalchemy/engine/base.py", line 3274, in connect
    return self._connection_cls(self)
  File "/opt/anaconda3/envs/webAi/lib/python3.10/site-packages/sqlalchemy/engine/base.py", line 148, in __init__
    Connection._handle_dbapi_exception_noconnection(
  File "/opt/anaconda3/envs/webAi/lib/python3.10/site-packages/sqlalchemy/engine/base.py", line 2439, in _handle_dbapi_exception_noconnection
    raise sqlalchemy_exception.with_traceback(exc_info[2]) from e
  File "/opt/anaconda3/envs/webAi/lib/python3.10/site-packages/sqlalchemy/engine/base.py", line 146, in __init__
    self._dbapi_connection = engine.raw_connection()
  File "/opt/anaconda3/envs/webAi/lib/python3.10/site-packages/sqlalchemy/engine/base.py", line 3298, in raw_connection
    return self.pool.connect()
  File "/opt/anaconda3/envs/webAi/lib/python3.10/site-packages/sqlalchemy/pool/base.py", line 449, in connect
    return _ConnectionFairy._checkout(self)
  File "/opt/anaconda3/envs/webAi/lib/python3.10/site-packages/sqlalchemy/pool/base.py", line 1264, in _checkout
    fairy = _ConnectionRecord.checkout(pool)
  File "/opt/anaconda3/envs/webAi/lib/python3.10/site-packages/sqlalchemy/pool/base.py", line 718, in checkout
    with util.safe_reraise():
  File "/opt/anaconda3/envs/webAi/lib/python3.10/site-packages/sqlalchemy/util/langhelpers.py", line 146, in __exit__
    raise exc_value.with_traceback(exc_tb)
  File "/opt/anaconda3/envs/webAi/lib/python3.10/site-packages/sqlalchemy/pool/base.py", line 716, in checkout
    dbapi_connection = rec.get_connection()
  File "/opt/anaconda3/envs/webAi/lib/python3.10/site-packages/sqlalchemy/pool/base.py", line 838, in get_connection
    self.__connect()
  File "/opt/anaconda3/envs/webAi/lib/python3.10/site-packages/sqlalchemy/pool/base.py", line 901, in __connect
    with util.safe_reraise():
  File "/opt/anaconda3/envs/webAi/lib/python3.10/site-packages/sqlalchemy/util/langhelpers.py", line 146, in __exit__
    raise exc_value.with_traceback(exc_tb)
  File "/opt/anaconda3/envs/webAi/lib/python3.10/site-packages/sqlalchemy/pool/base.py", line 897, in __connect
    self.dbapi_connection = connection = pool._invoke_creator(self)
  File "/opt/anaconda3/envs/webAi/lib/python3.10/site-packages/sqlalchemy/engine/create.py", line 646, in connect
    return dialect.connect(*cargs, **cparams)
  File "/opt/anaconda3/envs/webAi/lib/python3.10/site-packages/sqlalchemy/engine/default.py", line 625, in connect
    return self.loaded_dbapi.connect(*cargs, **cparams)  # type: ignore[no-any-return]  # NOQA: E501
  File "/opt/anaconda3/envs/webAi/lib/python3.10/site-packages/sqlalchemy/dialects/mysql/asyncmy.py", line 286, in connect
    await_only(creator_fn(*arg, **kw)),
  File "/opt/anaconda3/envs/webAi/lib/python3.10/site-packages/sqlalchemy/util/_concurrency_py3k.py", line 132, in await_only
    return current.parent.switch(awaitable)  # type: ignore[no-any-return,attr-defined] # noqa: E501
  File "/opt/anaconda3/envs/webAi/lib/python3.10/site-packages/sqlalchemy/util/_concurrency_py3k.py", line 196, in greenlet_spawn
    value = await result
  File "asyncmy/connection.pyx", line 1345, in _connect
  File "asyncmy/connection.pyx", line 590, in connect
sqlalchemy.exc.OperationalError: (asyncmy.errors.OperationalError) (2003, "Can't connect to MySQL server on 'localhost' ([Errno 111] Connect call failed ('127.0.0.1', 3306))")
(Background on this error at: https://sqlalche.me/e/20/e3q8)
[Debug] getting db...
[Debug] user login: test_user
INFO:     10.19.98.74:0 - "POST /api/auth/login HTTP/1.0" 500 Internal Server Error
ERROR:    Exception in ASGI application
Traceback (most recent call last):
  File "asyncmy/connection.pyx", line 567, in asyncmy.connection.Connection.connect
  File "asyncmy/connection.pyx", line 558, in asyncmy.connection.Connection.connect
  File "/opt/anaconda3/envs/webAi/lib/python3.10/asyncio/tasks.py", line 445, in wait_for
    return fut.result()
  File "/opt/anaconda3/envs/webAi/lib/python3.10/asyncio/streams.py", line 48, in open_connection
    transport, _ = await loop.create_connection(
  File "/opt/anaconda3/envs/webAi/lib/python3.10/asyncio/base_events.py", line 1076, in create_connection
    raise exceptions[0]
  File "/opt/anaconda3/envs/webAi/lib/python3.10/asyncio/base_events.py", line 1060, in create_connection
    sock = await self._connect_sock(
  File "/opt/anaconda3/envs/webAi/lib/python3.10/asyncio/base_events.py", line 969, in _connect_sock
    await self.sock_connect(sock, address)
  File "/opt/anaconda3/envs/webAi/lib/python3.10/asyncio/selector_events.py", line 501, in sock_connect
    return await fut
  File "/opt/anaconda3/envs/webAi/lib/python3.10/asyncio/selector_events.py", line 541, in _sock_connect_cb
    raise OSError(err, f'Connect call failed {address}')
ConnectionRefusedError: [Errno 111] Connect call failed ('127.0.0.1', 3306)

The above exception was the direct cause of the following exception:

Traceback (most recent call last):
  File "/opt/anaconda3/envs/webAi/lib/python3.10/site-packages/sqlalchemy/engine/base.py", line 146, in __init__
    self._dbapi_connection = engine.raw_connection()
  File "/opt/anaconda3/envs/webAi/lib/python3.10/site-packages/sqlalchemy/engine/base.py", line 3298, in raw_connection
    return self.pool.connect()
  File "/opt/anaconda3/envs/webAi/lib/python3.10/site-packages/sqlalchemy/pool/base.py", line 449, in connect
    return _ConnectionFairy._checkout(self)
  File "/opt/anaconda3/envs/webAi/lib/python3.10/site-packages/sqlalchemy/pool/base.py", line 1264, in _checkout
    fairy = _ConnectionRecord.checkout(pool)
  File "/opt/anaconda3/envs/webAi/lib/python3.10/site-packages/sqlalchemy/pool/base.py", line 718, in checkout
    with util.safe_reraise():
  File "/opt/anaconda3/envs/webAi/lib/python3.10/site-packages/sqlalchemy/util/langhelpers.py", line 146, in __exit__
    raise exc_value.with_traceback(exc_tb)
  File "/opt/anaconda3/envs/webAi/lib/python3.10/site-packages/sqlalchemy/pool/base.py", line 716, in checkout
    dbapi_connection = rec.get_connection()
  File "/opt/anaconda3/envs/webAi/lib/python3.10/site-packages/sqlalchemy/pool/base.py", line 838, in get_connection
    self.__connect()
  File "/opt/anaconda3/envs/webAi/lib/python3.10/site-packages/sqlalchemy/pool/base.py", line 901, in __connect
    with util.safe_reraise():
  File "/opt/anaconda3/envs/webAi/lib/python3.10/site-packages/sqlalchemy/util/langhelpers.py", line 146, in __exit__
    raise exc_value.with_traceback(exc_tb)
  File "/opt/anaconda3/envs/webAi/lib/python3.10/site-packages/sqlalchemy/pool/base.py", line 897, in __connect
    self.dbapi_connection = connection = pool._invoke_creator(self)
  File "/opt/anaconda3/envs/webAi/lib/python3.10/site-packages/sqlalchemy/engine/create.py", line 646, in connect
    return dialect.connect(*cargs, **cparams)
  File "/opt/anaconda3/envs/webAi/lib/python3.10/site-packages/sqlalchemy/engine/default.py", line 625, in connect
    return self.loaded_dbapi.connect(*cargs, **cparams)  # type: ignore[no-any-return]  # NOQA: E501
  File "/opt/anaconda3/envs/webAi/lib/python3.10/site-packages/sqlalchemy/dialects/mysql/asyncmy.py", line 286, in connect
    await_only(creator_fn(*arg, **kw)),
  File "/opt/anaconda3/envs/webAi/lib/python3.10/site-packages/sqlalchemy/util/_concurrency_py3k.py", line 132, in await_only
    return current.parent.switch(awaitable)  # type: ignore[no-any-return,attr-defined] # noqa: E501
  File "/opt/anaconda3/envs/webAi/lib/python3.10/site-packages/sqlalchemy/util/_concurrency_py3k.py", line 196, in greenlet_spawn
    value = await result
  File "asyncmy/connection.pyx", line 1345, in _connect
  File "asyncmy/connection.pyx", line 590, in connect
asyncmy.errors.OperationalError: (2003, "Can't connect to MySQL server on 'localhost' ([Errno 111] Connect call failed ('127.0.0.1', 3306))")

The above exception was the direct cause of the following exception:

Traceback (most recent call last):
  File "/opt/anaconda3/envs/webAi/lib/python3.10/site-packages/uvicorn/protocols/http/h11_impl.py", line 403, in run_asgi
    result = await app(  # type: ignore[func-returns-value]
  File "/opt/anaconda3/envs/webAi/lib/python3.10/site-packages/uvicorn/middleware/proxy_headers.py", line 60, in __call__
    return await self.app(scope, receive, send)
  File "/opt/anaconda3/envs/webAi/lib/python3.10/site-packages/fastapi/applications.py", line 1054, in __call__
    await super().__call__(scope, receive, send)
  File "/opt/anaconda3/envs/webAi/lib/python3.10/site-packages/starlette/applications.py", line 112, in __call__
    await self.middleware_stack(scope, receive, send)
  File "/opt/anaconda3/envs/webAi/lib/python3.10/site-packages/starlette/middleware/errors.py", line 187, in __call__
    raise exc
  File "/opt/anaconda3/envs/webAi/lib/python3.10/site-packages/starlette/middleware/errors.py", line 165, in __call__
    await self.app(scope, receive, _send)
  File "/opt/anaconda3/envs/webAi/lib/python3.10/site-packages/starlette/middleware/cors.py", line 93, in __call__
    await self.simple_response(scope, receive, send, request_headers=headers)
  File "/opt/anaconda3/envs/webAi/lib/python3.10/site-packages/starlette/middleware/cors.py", line 144, in simple_response
    await self.app(scope, receive, send)
  File "/opt/anaconda3/envs/webAi/lib/python3.10/site-packages/starlette/middleware/base.py", line 173, in __call__
    with recv_stream, send_stream, collapse_excgroups():
  File "/opt/anaconda3/envs/webAi/lib/python3.10/contextlib.py", line 153, in __exit__
    self.gen.throw(typ, value, traceback)
  File "/opt/anaconda3/envs/webAi/lib/python3.10/site-packages/starlette/_utils.py", line 82, in collapse_excgroups
    raise exc
  File "/opt/anaconda3/envs/webAi/lib/python3.10/site-packages/starlette/middleware/base.py", line 175, in __call__
    response = await self.dispatch_func(request, call_next)
  File "/home/jhyang/AiWeb/webAi_backEnd/app/main.py", line 20, in add_process_time_header
    response = await call_next(request)
  File "/opt/anaconda3/envs/webAi/lib/python3.10/site-packages/starlette/middleware/base.py", line 153, in call_next
    raise app_exc
  File "/opt/anaconda3/envs/webAi/lib/python3.10/site-packages/starlette/middleware/base.py", line 140, in coro
    await self.app(scope, receive_or_disconnect, send_no_error)
  File "/opt/anaconda3/envs/webAi/lib/python3.10/site-packages/starlette/middleware/exceptions.py", line 62, in __call__
    await wrap_app_handling_exceptions(self.app, conn)(scope, receive, send)
  File "/opt/anaconda3/envs/webAi/lib/python3.10/site-packages/starlette/_exception_handler.py", line 53, in wrapped_app
    raise exc
  File "/opt/anaconda3/envs/webAi/lib/python3.10/site-packages/starlette/_exception_handler.py", line 42, in wrapped_app
    await app(scope, receive, sender)
  File "/opt/anaconda3/envs/webAi/lib/python3.10/site-packages/starlette/routing.py", line 714, in __call__
    await self.middleware_stack(scope, receive, send)
  File "/opt/anaconda3/envs/webAi/lib/python3.10/site-packages/starlette/routing.py", line 734, in app
    await route.handle(scope, receive, send)
  File "/opt/anaconda3/envs/webAi/lib/python3.10/site-packages/starlette/routing.py", line 288, in handle
    await self.app(scope, receive, send)
  File "/opt/anaconda3/envs/webAi/lib/python3.10/site-packages/starlette/routing.py", line 76, in app
    await wrap_app_handling_exceptions(app, request)(scope, receive, send)
  File "/opt/anaconda3/envs/webAi/lib/python3.10/site-packages/starlette/_exception_handler.py", line 53, in wrapped_app
    raise exc
  File "/opt/anaconda3/envs/webAi/lib/python3.10/site-packages/starlette/_exception_handler.py", line 42, in wrapped_app
    await app(scope, receive, sender)
  File "/opt/anaconda3/envs/webAi/lib/python3.10/site-packages/starlette/routing.py", line 73, in app
    response = await f(request)
  File "/opt/anaconda3/envs/webAi/lib/python3.10/site-packages/fastapi/routing.py", line 301, in app
    raw_response = await run_endpoint_function(
  File "/opt/anaconda3/envs/webAi/lib/python3.10/site-packages/fastapi/routing.py", line 212, in run_endpoint_function
    return await dependant.call(**values)
  File "/home/jhyang/AiWeb/webAi_backEnd/app/routers/auth.py", line 83, in login
    result = await db.execute(
  File "/opt/anaconda3/envs/webAi/lib/python3.10/site-packages/sqlalchemy/ext/asyncio/session.py", line 463, in execute
    result = await greenlet_spawn(
  File "/opt/anaconda3/envs/webAi/lib/python3.10/site-packages/sqlalchemy/util/_concurrency_py3k.py", line 201, in greenlet_spawn
    result = context.throw(*sys.exc_info())
  File "/opt/anaconda3/envs/webAi/lib/python3.10/site-packages/sqlalchemy/orm/session.py", line 2365, in execute
    return self._execute_internal(
  File "/opt/anaconda3/envs/webAi/lib/python3.10/site-packages/sqlalchemy/orm/session.py", line 2241, in _execute_internal
    conn = self._connection_for_bind(bind)
  File "/opt/anaconda3/envs/webAi/lib/python3.10/site-packages/sqlalchemy/orm/session.py", line 2110, in _connection_for_bind
    return trans._connection_for_bind(engine, execution_options)
  File "<string>", line 2, in _connection_for_bind
  File "/opt/anaconda3/envs/webAi/lib/python3.10/site-packages/sqlalchemy/orm/state_changes.py", line 139, in _go
    ret_value = fn(self, *arg, **kw)
  File "/opt/anaconda3/envs/webAi/lib/python3.10/site-packages/sqlalchemy/orm/session.py", line 1189, in _connection_for_bind
    conn = bind.connect()
  File "/opt/anaconda3/envs/webAi/lib/python3.10/site-packages/sqlalchemy/engine/base.py", line 3274, in connect
    return self._connection_cls(self)
  File "/opt/anaconda3/envs/webAi/lib/python3.10/site-packages/sqlalchemy/engine/base.py", line 148, in __init__
    Connection._handle_dbapi_exception_noconnection(
  File "/opt/anaconda3/envs/webAi/lib/python3.10/site-packages/sqlalchemy/engine/base.py", line 2439, in _handle_dbapi_exception_noconnection
    raise sqlalchemy_exception.with_traceback(exc_info[2]) from e
  File "/opt/anaconda3/envs/webAi/lib/python3.10/site-packages/sqlalchemy/engine/base.py", line 146, in __init__
    self._dbapi_connection = engine.raw_connection()
  File "/opt/anaconda3/envs/webAi/lib/python3.10/site-packages/sqlalchemy/engine/base.py", line 3298, in raw_connection
    return self.pool.connect()
  File "/opt/anaconda3/envs/webAi/lib/python3.10/site-packages/sqlalchemy/pool/base.py", line 449, in connect
    return _ConnectionFairy._checkout(self)
  File "/opt/anaconda3/envs/webAi/lib/python3.10/site-packages/sqlalchemy/pool/base.py", line 1264, in _checkout
    fairy = _ConnectionRecord.checkout(pool)
  File "/opt/anaconda3/envs/webAi/lib/python3.10/site-packages/sqlalchemy/pool/base.py", line 718, in checkout
    with util.safe_reraise():
  File "/opt/anaconda3/envs/webAi/lib/python3.10/site-packages/sqlalchemy/util/langhelpers.py", line 146, in __exit__
    raise exc_value.with_traceback(exc_tb)
  File "/opt/anaconda3/envs/webAi/lib/python3.10/site-packages/sqlalchemy/pool/base.py", line 716, in checkout
    dbapi_connection = rec.get_connection()
  File "/opt/anaconda3/envs/webAi/lib/python3.10/site-packages/sqlalchemy/pool/base.py", line 838, in get_connection
    self.__connect()
  File "/opt/anaconda3/envs/webAi/lib/python3.10/site-packages/sqlalchemy/pool/base.py", line 901, in __connect
    with util.safe_reraise():
  File "/opt/anaconda3/envs/webAi/lib/python3.10/site-packages/sqlalchemy/util/langhelpers.py", line 146, in __exit__
    raise exc_value.with_traceback(exc_tb)
  File "/opt/anaconda3/envs/webAi/lib/python3.10/site-packages/sqlalchemy/pool/base.py", line 897, in __connect
    self.dbapi_connection = connection = pool._invoke_creator(self)
  File "/opt/anaconda3/envs/webAi/lib/python3.10/site-packages/sqlalchemy/engine/create.py", line 646, in connect
    return dialect.connect(*cargs, **cparams)
  File "/opt/anaconda3/envs/webAi/lib/python3.10/site-packages/sqlalchemy/engine/default.py", line 625, in connect
    return self.loaded_dbapi.connect(*cargs, **cparams)  # type: ignore[no-any-return]  # NOQA: E501
  File "/opt/anaconda3/envs/webAi/lib/python3.10/site-packages/sqlalchemy/dialects/mysql/asyncmy.py", line 286, in connect
    await_only(creator_fn(*arg, **kw)),
  File "/opt/anaconda3/envs/webAi/lib/python3.10/site-packages/sqlalchemy/util/_concurrency_py3k.py", line 132, in await_only
    return current.parent.switch(awaitable)  # type: ignore[no-any-return,attr-defined] # noqa: E501
  File "/opt/anaconda3/envs/webAi/lib/python3.10/site-packages/sqlalchemy/util/_concurrency_py3k.py", line 196, in greenlet_spawn
    value = await result
  File "asyncmy/connection.pyx", line 1345, in _connect
  File "asyncmy/connection.pyx", line 590, in connect
sqlalchemy.exc.OperationalError: (asyncmy.errors.OperationalError) (2003, "Can't connect to MySQL server on 'localhost' ([Errno 111] Connect call failed ('127.0.0.1', 3306))")
(Background on this error at: https://sqlalche.me/e/20/e3q8)
[Debug] getting db...
[Debug] user login: test_user
INFO:     10.12.49.105:0 - "POST /api/auth/login HTTP/1.0" 500 Internal Server Error
ERROR:    Exception in ASGI application
Traceback (most recent call last):
  File "asyncmy/connection.pyx", line 567, in asyncmy.connection.Connection.connect
  File "asyncmy/connection.pyx", line 558, in asyncmy.connection.Connection.connect
  File "/opt/anaconda3/envs/webAi/lib/python3.10/asyncio/tasks.py", line 445, in wait_for
    return fut.result()
  File "/opt/anaconda3/envs/webAi/lib/python3.10/asyncio/streams.py", line 48, in open_connection
    transport, _ = await loop.create_connection(
  File "/opt/anaconda3/envs/webAi/lib/python3.10/asyncio/base_events.py", line 1076, in create_connection
    raise exceptions[0]
  File "/opt/anaconda3/envs/webAi/lib/python3.10/asyncio/base_events.py", line 1060, in create_connection
    sock = await self._connect_sock(
  File "/opt/anaconda3/envs/webAi/lib/python3.10/asyncio/base_events.py", line 969, in _connect_sock
    await self.sock_connect(sock, address)
  File "/opt/anaconda3/envs/webAi/lib/python3.10/asyncio/selector_events.py", line 501, in sock_connect
    return await fut
  File "/opt/anaconda3/envs/webAi/lib/python3.10/asyncio/selector_events.py", line 541, in _sock_connect_cb
    raise OSError(err, f'Connect call failed {address}')
ConnectionRefusedError: [Errno 111] Connect call failed ('127.0.0.1', 3306)

The above exception was the direct cause of the following exception:

Traceback (most recent call last):
  File "/opt/anaconda3/envs/webAi/lib/python3.10/site-packages/sqlalchemy/engine/base.py", line 146, in __init__
    self._dbapi_connection = engine.raw_connection()
  File "/opt/anaconda3/envs/webAi/lib/python3.10/site-packages/sqlalchemy/engine/base.py", line 3298, in raw_connection
    return self.pool.connect()
  File "/opt/anaconda3/envs/webAi/lib/python3.10/site-packages/sqlalchemy/pool/base.py", line 449, in connect
    return _ConnectionFairy._checkout(self)
  File "/opt/anaconda3/envs/webAi/lib/python3.10/site-packages/sqlalchemy/pool/base.py", line 1264, in _checkout
    fairy = _ConnectionRecord.checkout(pool)
  File "/opt/anaconda3/envs/webAi/lib/python3.10/site-packages/sqlalchemy/pool/base.py", line 718, in checkout
    with util.safe_reraise():
  File "/opt/anaconda3/envs/webAi/lib/python3.10/site-packages/sqlalchemy/util/langhelpers.py", line 146, in __exit__
    raise exc_value.with_traceback(exc_tb)
  File "/opt/anaconda3/envs/webAi/lib/python3.10/site-packages/sqlalchemy/pool/base.py", line 716, in checkout
    dbapi_connection = rec.get_connection()
  File "/opt/anaconda3/envs/webAi/lib/python3.10/site-packages/sqlalchemy/pool/base.py", line 838, in get_connection
    self.__connect()
  File "/opt/anaconda3/envs/webAi/lib/python3.10/site-packages/sqlalchemy/pool/base.py", line 901, in __connect
    with util.safe_reraise():
  File "/opt/anaconda3/envs/webAi/lib/python3.10/site-packages/sqlalchemy/util/langhelpers.py", line 146, in __exit__
    raise exc_value.with_traceback(exc_tb)
  File "/opt/anaconda3/envs/webAi/lib/python3.10/site-packages/sqlalchemy/pool/base.py", line 897, in __connect
    self.dbapi_connection = connection = pool._invoke_creator(self)
  File "/opt/anaconda3/envs/webAi/lib/python3.10/site-packages/sqlalchemy/engine/create.py", line 646, in connect
    return dialect.connect(*cargs, **cparams)
  File "/opt/anaconda3/envs/webAi/lib/python3.10/site-packages/sqlalchemy/engine/default.py", line 625, in connect
    return self.loaded_dbapi.connect(*cargs, **cparams)  # type: ignore[no-any-return]  # NOQA: E501
  File "/opt/anaconda3/envs/webAi/lib/python3.10/site-packages/sqlalchemy/dialects/mysql/asyncmy.py", line 286, in connect
    await_only(creator_fn(*arg, **kw)),
  File "/opt/anaconda3/envs/webAi/lib/python3.10/site-packages/sqlalchemy/util/_concurrency_py3k.py", line 132, in await_only
    return current.parent.switch(awaitable)  # type: ignore[no-any-return,attr-defined] # noqa: E501
  File "/opt/anaconda3/envs/webAi/lib/python3.10/site-packages/sqlalchemy/util/_concurrency_py3k.py", line 196, in greenlet_spawn
    value = await result
  File "asyncmy/connection.pyx", line 1345, in _connect
  File "asyncmy/connection.pyx", line 590, in connect
asyncmy.errors.OperationalError: (2003, "Can't connect to MySQL server on 'localhost' ([Errno 111] Connect call failed ('127.0.0.1', 3306))")

The above exception was the direct cause of the following exception:

Traceback (most recent call last):
  File "/opt/anaconda3/envs/webAi/lib/python3.10/site-packages/uvicorn/protocols/http/h11_impl.py", line 403, in run_asgi
    result = await app(  # type: ignore[func-returns-value]
  File "/opt/anaconda3/envs/webAi/lib/python3.10/site-packages/uvicorn/middleware/proxy_headers.py", line 60, in __call__
    return await self.app(scope, receive, send)
  File "/opt/anaconda3/envs/webAi/lib/python3.10/site-packages/fastapi/applications.py", line 1054, in __call__
    await super().__call__(scope, receive, send)
  File "/opt/anaconda3/envs/webAi/lib/python3.10/site-packages/starlette/applications.py", line 112, in __call__
    await self.middleware_stack(scope, receive, send)
  File "/opt/anaconda3/envs/webAi/lib/python3.10/site-packages/starlette/middleware/errors.py", line 187, in __call__
    raise exc
  File "/opt/anaconda3/envs/webAi/lib/python3.10/site-packages/starlette/middleware/errors.py", line 165, in __call__
    await self.app(scope, receive, _send)
  File "/opt/anaconda3/envs/webAi/lib/python3.10/site-packages/starlette/middleware/cors.py", line 93, in __call__
    await self.simple_response(scope, receive, send, request_headers=headers)
  File "/opt/anaconda3/envs/webAi/lib/python3.10/site-packages/starlette/middleware/cors.py", line 144, in simple_response
    await self.app(scope, receive, send)
  File "/opt/anaconda3/envs/webAi/lib/python3.10/site-packages/starlette/middleware/base.py", line 173, in __call__
    with recv_stream, send_stream, collapse_excgroups():
  File "/opt/anaconda3/envs/webAi/lib/python3.10/contextlib.py", line 153, in __exit__
    self.gen.throw(typ, value, traceback)
  File "/opt/anaconda3/envs/webAi/lib/python3.10/site-packages/starlette/_utils.py", line 82, in collapse_excgroups
    raise exc
  File "/opt/anaconda3/envs/webAi/lib/python3.10/site-packages/starlette/middleware/base.py", line 175, in __call__
    response = await self.dispatch_func(request, call_next)
  File "/home/jhyang/AiWeb/webAi_backEnd/app/main.py", line 20, in add_process_time_header
    response = await call_next(request)
  File "/opt/anaconda3/envs/webAi/lib/python3.10/site-packages/starlette/middleware/base.py", line 153, in call_next
    raise app_exc
  File "/opt/anaconda3/envs/webAi/lib/python3.10/site-packages/starlette/middleware/base.py", line 140, in coro
    await self.app(scope, receive_or_disconnect, send_no_error)
  File "/opt/anaconda3/envs/webAi/lib/python3.10/site-packages/starlette/middleware/exceptions.py", line 62, in __call__
    await wrap_app_handling_exceptions(self.app, conn)(scope, receive, send)
  File "/opt/anaconda3/envs/webAi/lib/python3.10/site-packages/starlette/_exception_handler.py", line 53, in wrapped_app
    raise exc
  File "/opt/anaconda3/envs/webAi/lib/python3.10/site-packages/starlette/_exception_handler.py", line 42, in wrapped_app
    await app(scope, receive, sender)
  File "/opt/anaconda3/envs/webAi/lib/python3.10/site-packages/starlette/routing.py", line 714, in __call__
    await self.middleware_stack(scope, receive, send)
  File "/opt/anaconda3/envs/webAi/lib/python3.10/site-packages/starlette/routing.py", line 734, in app
    await route.handle(scope, receive, send)
  File "/opt/anaconda3/envs/webAi/lib/python3.10/site-packages/starlette/routing.py", line 288, in handle
    await self.app(scope, receive, send)
  File "/opt/anaconda3/envs/webAi/lib/python3.10/site-packages/starlette/routing.py", line 76, in app
    await wrap_app_handling_exceptions(app, request)(scope, receive, send)
  File "/opt/anaconda3/envs/webAi/lib/python3.10/site-packages/starlette/_exception_handler.py", line 53, in wrapped_app
    raise exc
  File "/opt/anaconda3/envs/webAi/lib/python3.10/site-packages/starlette/_exception_handler.py", line 42, in wrapped_app
    await app(scope, receive, sender)
  File "/opt/anaconda3/envs/webAi/lib/python3.10/site-packages/starlette/routing.py", line 73, in app
    response = await f(request)
  File "/opt/anaconda3/envs/webAi/lib/python3.10/site-packages/fastapi/routing.py", line 301, in app
    raw_response = await run_endpoint_function(
  File "/opt/anaconda3/envs/webAi/lib/python3.10/site-packages/fastapi/routing.py", line 212, in run_endpoint_function
    return await dependant.call(**values)
  File "/home/jhyang/AiWeb/webAi_backEnd/app/routers/auth.py", line 83, in login
    result = await db.execute(
  File "/opt/anaconda3/envs/webAi/lib/python3.10/site-packages/sqlalchemy/ext/asyncio/session.py", line 463, in execute
    result = await greenlet_spawn(
  File "/opt/anaconda3/envs/webAi/lib/python3.10/site-packages/sqlalchemy/util/_concurrency_py3k.py", line 201, in greenlet_spawn
    result = context.throw(*sys.exc_info())
  File "/opt/anaconda3/envs/webAi/lib/python3.10/site-packages/sqlalchemy/orm/session.py", line 2365, in execute
    return self._execute_internal(
  File "/opt/anaconda3/envs/webAi/lib/python3.10/site-packages/sqlalchemy/orm/session.py", line 2241, in _execute_internal
    conn = self._connection_for_bind(bind)
  File "/opt/anaconda3/envs/webAi/lib/python3.10/site-packages/sqlalchemy/orm/session.py", line 2110, in _connection_for_bind
    return trans._connection_for_bind(engine, execution_options)
  File "<string>", line 2, in _connection_for_bind
  File "/opt/anaconda3/envs/webAi/lib/python3.10/site-packages/sqlalchemy/orm/state_changes.py", line 139, in _go
    ret_value = fn(self, *arg, **kw)
  File "/opt/anaconda3/envs/webAi/lib/python3.10/site-packages/sqlalchemy/orm/session.py", line 1189, in _connection_for_bind
    conn = bind.connect()
  File "/opt/anaconda3/envs/webAi/lib/python3.10/site-packages/sqlalchemy/engine/base.py", line 3274, in connect
    return self._connection_cls(self)
  File "/opt/anaconda3/envs/webAi/lib/python3.10/site-packages/sqlalchemy/engine/base.py", line 148, in __init__
    Connection._handle_dbapi_exception_noconnection(
  File "/opt/anaconda3/envs/webAi/lib/python3.10/site-packages/sqlalchemy/engine/base.py", line 2439, in _handle_dbapi_exception_noconnection
    raise sqlalchemy_exception.with_traceback(exc_info[2]) from e
  File "/opt/anaconda3/envs/webAi/lib/python3.10/site-packages/sqlalchemy/engine/base.py", line 146, in __init__
    self._dbapi_connection = engine.raw_connection()
  File "/opt/anaconda3/envs/webAi/lib/python3.10/site-packages/sqlalchemy/engine/base.py", line 3298, in raw_connection
    return self.pool.connect()
  File "/opt/anaconda3/envs/webAi/lib/python3.10/site-packages/sqlalchemy/pool/base.py", line 449, in connect
    return _ConnectionFairy._checkout(self)
  File "/opt/anaconda3/envs/webAi/lib/python3.10/site-packages/sqlalchemy/pool/base.py", line 1264, in _checkout
    fairy = _ConnectionRecord.checkout(pool)
  File "/opt/anaconda3/envs/webAi/lib/python3.10/site-packages/sqlalchemy/pool/base.py", line 718, in checkout
    with util.safe_reraise():
  File "/opt/anaconda3/envs/webAi/lib/python3.10/site-packages/sqlalchemy/util/langhelpers.py", line 146, in __exit__
    raise exc_value.with_traceback(exc_tb)
  File "/opt/anaconda3/envs/webAi/lib/python3.10/site-packages/sqlalchemy/pool/base.py", line 716, in checkout
    dbapi_connection = rec.get_connection()
  File "/opt/anaconda3/envs/webAi/lib/python3.10/site-packages/sqlalchemy/pool/base.py", line 838, in get_connection
    self.__connect()
  File "/opt/anaconda3/envs/webAi/lib/python3.10/site-packages/sqlalchemy/pool/base.py", line 901, in __connect
    with util.safe_reraise():
  File "/opt/anaconda3/envs/webAi/lib/python3.10/site-packages/sqlalchemy/util/langhelpers.py", line 146, in __exit__
    raise exc_value.with_traceback(exc_tb)
  File "/opt/anaconda3/envs/webAi/lib/python3.10/site-packages/sqlalchemy/pool/base.py", line 897, in __connect
    self.dbapi_connection = connection = pool._invoke_creator(self)
  File "/opt/anaconda3/envs/webAi/lib/python3.10/site-packages/sqlalchemy/engine/create.py", line 646, in connect
    return dialect.connect(*cargs, **cparams)
  File "/opt/anaconda3/envs/webAi/lib/python3.10/site-packages/sqlalchemy/engine/default.py", line 625, in connect
    return self.loaded_dbapi.connect(*cargs, **cparams)  # type: ignore[no-any-return]  # NOQA: E501
  File "/opt/anaconda3/envs/webAi/lib/python3.10/site-packages/sqlalchemy/dialects/mysql/asyncmy.py", line 286, in connect
    await_only(creator_fn(*arg, **kw)),
  File "/opt/anaconda3/envs/webAi/lib/python3.10/site-packages/sqlalchemy/util/_concurrency_py3k.py", line 132, in await_only
    return current.parent.switch(awaitable)  # type: ignore[no-any-return,attr-defined] # noqa: E501
  File "/opt/anaconda3/envs/webAi/lib/python3.10/site-packages/sqlalchemy/util/_concurrency_py3k.py", line 196, in greenlet_spawn
    value = await result
  File "asyncmy/connection.pyx", line 1345, in _connect
  File "asyncmy/connection.pyx", line 590, in connect
sqlalchemy.exc.OperationalError: (asyncmy.errors.OperationalError) (2003, "Can't connect to MySQL server on 'localhost' ([Errno 111] Connect call failed ('127.0.0.1', 3306))")
(Background on this error at: https://sqlalche.me/e/20/e3q8)
INFO:     10.12.49.105:0 - "OPTIONS /api/auth/login HTTP/1.0" 400 Bad Request
INFO:     10.12.49.105:0 - "OPTIONS /api/auth/login HTTP/1.0" 400 Bad Request
[Debug] getting db...
[Debug] user login: Admin
INFO:     10.12.49.105:0 - "POST /api/auth/login HTTP/1.0" 500 Internal Server Error
ERROR:    Exception in ASGI application
Traceback (most recent call last):
  File "asyncmy/connection.pyx", line 567, in asyncmy.connection.Connection.connect
  File "asyncmy/connection.pyx", line 558, in asyncmy.connection.Connection.connect
  File "/opt/anaconda3/envs/webAi/lib/python3.10/asyncio/tasks.py", line 445, in wait_for
    return fut.result()
  File "/opt/anaconda3/envs/webAi/lib/python3.10/asyncio/streams.py", line 48, in open_connection
    transport, _ = await loop.create_connection(
  File "/opt/anaconda3/envs/webAi/lib/python3.10/asyncio/base_events.py", line 1076, in create_connection
    raise exceptions[0]
  File "/opt/anaconda3/envs/webAi/lib/python3.10/asyncio/base_events.py", line 1060, in create_connection
    sock = await self._connect_sock(
  File "/opt/anaconda3/envs/webAi/lib/python3.10/asyncio/base_events.py", line 969, in _connect_sock
    await self.sock_connect(sock, address)
  File "/opt/anaconda3/envs/webAi/lib/python3.10/asyncio/selector_events.py", line 501, in sock_connect
    return await fut
  File "/opt/anaconda3/envs/webAi/lib/python3.10/asyncio/selector_events.py", line 541, in _sock_connect_cb
    raise OSError(err, f'Connect call failed {address}')
ConnectionRefusedError: [Errno 111] Connect call failed ('127.0.0.1', 3306)

The above exception was the direct cause of the following exception:

Traceback (most recent call last):
  File "/opt/anaconda3/envs/webAi/lib/python3.10/site-packages/sqlalchemy/engine/base.py", line 146, in __init__
    self._dbapi_connection = engine.raw_connection()
  File "/opt/anaconda3/envs/webAi/lib/python3.10/site-packages/sqlalchemy/engine/base.py", line 3298, in raw_connection
    return self.pool.connect()
  File "/opt/anaconda3/envs/webAi/lib/python3.10/site-packages/sqlalchemy/pool/base.py", line 449, in connect
    return _ConnectionFairy._checkout(self)
  File "/opt/anaconda3/envs/webAi/lib/python3.10/site-packages/sqlalchemy/pool/base.py", line 1264, in _checkout
    fairy = _ConnectionRecord.checkout(pool)
  File "/opt/anaconda3/envs/webAi/lib/python3.10/site-packages/sqlalchemy/pool/base.py", line 718, in checkout
    with util.safe_reraise():
  File "/opt/anaconda3/envs/webAi/lib/python3.10/site-packages/sqlalchemy/util/langhelpers.py", line 146, in __exit__
    raise exc_value.with_traceback(exc_tb)
  File "/opt/anaconda3/envs/webAi/lib/python3.10/site-packages/sqlalchemy/pool/base.py", line 716, in checkout
    dbapi_connection = rec.get_connection()
  File "/opt/anaconda3/envs/webAi/lib/python3.10/site-packages/sqlalchemy/pool/base.py", line 838, in get_connection
    self.__connect()
  File "/opt/anaconda3/envs/webAi/lib/python3.10/site-packages/sqlalchemy/pool/base.py", line 901, in __connect
    with util.safe_reraise():
  File "/opt/anaconda3/envs/webAi/lib/python3.10/site-packages/sqlalchemy/util/langhelpers.py", line 146, in __exit__
    raise exc_value.with_traceback(exc_tb)
  File "/opt/anaconda3/envs/webAi/lib/python3.10/site-packages/sqlalchemy/pool/base.py", line 897, in __connect
    self.dbapi_connection = connection = pool._invoke_creator(self)
  File "/opt/anaconda3/envs/webAi/lib/python3.10/site-packages/sqlalchemy/engine/create.py", line 646, in connect
    return dialect.connect(*cargs, **cparams)
  File "/opt/anaconda3/envs/webAi/lib/python3.10/site-packages/sqlalchemy/engine/default.py", line 625, in connect
    return self.loaded_dbapi.connect(*cargs, **cparams)  # type: ignore[no-any-return]  # NOQA: E501
  File "/opt/anaconda3/envs/webAi/lib/python3.10/site-packages/sqlalchemy/dialects/mysql/asyncmy.py", line 286, in connect
    await_only(creator_fn(*arg, **kw)),
  File "/opt/anaconda3/envs/webAi/lib/python3.10/site-packages/sqlalchemy/util/_concurrency_py3k.py", line 132, in await_only
    return current.parent.switch(awaitable)  # type: ignore[no-any-return,attr-defined] # noqa: E501
  File "/opt/anaconda3/envs/webAi/lib/python3.10/site-packages/sqlalchemy/util/_concurrency_py3k.py", line 196, in greenlet_spawn
    value = await result
  File "asyncmy/connection.pyx", line 1345, in _connect
  File "asyncmy/connection.pyx", line 590, in connect
asyncmy.errors.OperationalError: (2003, "Can't connect to MySQL server on 'localhost' ([Errno 111] Connect call failed ('127.0.0.1', 3306))")

The above exception was the direct cause of the following exception:

Traceback (most recent call last):
  File "/opt/anaconda3/envs/webAi/lib/python3.10/site-packages/uvicorn/protocols/http/h11_impl.py", line 403, in run_asgi
    result = await app(  # type: ignore[func-returns-value]
  File "/opt/anaconda3/envs/webAi/lib/python3.10/site-packages/uvicorn/middleware/proxy_headers.py", line 60, in __call__
    return await self.app(scope, receive, send)
  File "/opt/anaconda3/envs/webAi/lib/python3.10/site-packages/fastapi/applications.py", line 1054, in __call__
    await super().__call__(scope, receive, send)
  File "/opt/anaconda3/envs/webAi/lib/python3.10/site-packages/starlette/applications.py", line 112, in __call__
    await self.middleware_stack(scope, receive, send)
  File "/opt/anaconda3/envs/webAi/lib/python3.10/site-packages/starlette/middleware/errors.py", line 187, in __call__
    raise exc
  File "/opt/anaconda3/envs/webAi/lib/python3.10/site-packages/starlette/middleware/errors.py", line 165, in __call__
    await self.app(scope, receive, _send)
  File "/opt/anaconda3/envs/webAi/lib/python3.10/site-packages/starlette/middleware/cors.py", line 93, in __call__
    await self.simple_response(scope, receive, send, request_headers=headers)
  File "/opt/anaconda3/envs/webAi/lib/python3.10/site-packages/starlette/middleware/cors.py", line 144, in simple_response
    await self.app(scope, receive, send)
  File "/opt/anaconda3/envs/webAi/lib/python3.10/site-packages/starlette/middleware/base.py", line 173, in __call__
    with recv_stream, send_stream, collapse_excgroups():
  File "/opt/anaconda3/envs/webAi/lib/python3.10/contextlib.py", line 153, in __exit__
    self.gen.throw(typ, value, traceback)
  File "/opt/anaconda3/envs/webAi/lib/python3.10/site-packages/starlette/_utils.py", line 82, in collapse_excgroups
    raise exc
  File "/opt/anaconda3/envs/webAi/lib/python3.10/site-packages/starlette/middleware/base.py", line 175, in __call__
    response = await self.dispatch_func(request, call_next)
  File "/home/jhyang/AiWeb/webAi_backEnd/app/main.py", line 20, in add_process_time_header
    response = await call_next(request)
  File "/opt/anaconda3/envs/webAi/lib/python3.10/site-packages/starlette/middleware/base.py", line 153, in call_next
    raise app_exc
  File "/opt/anaconda3/envs/webAi/lib/python3.10/site-packages/starlette/middleware/base.py", line 140, in coro
    await self.app(scope, receive_or_disconnect, send_no_error)
  File "/opt/anaconda3/envs/webAi/lib/python3.10/site-packages/starlette/middleware/exceptions.py", line 62, in __call__
    await wrap_app_handling_exceptions(self.app, conn)(scope, receive, send)
  File "/opt/anaconda3/envs/webAi/lib/python3.10/site-packages/starlette/_exception_handler.py", line 53, in wrapped_app
    raise exc
  File "/opt/anaconda3/envs/webAi/lib/python3.10/site-packages/starlette/_exception_handler.py", line 42, in wrapped_app
    await app(scope, receive, sender)
  File "/opt/anaconda3/envs/webAi/lib/python3.10/site-packages/starlette/routing.py", line 714, in __call__
    await self.middleware_stack(scope, receive, send)
  File "/opt/anaconda3/envs/webAi/lib/python3.10/site-packages/starlette/routing.py", line 734, in app
    await route.handle(scope, receive, send)
  File "/opt/anaconda3/envs/webAi/lib/python3.10/site-packages/starlette/routing.py", line 288, in handle
    await self.app(scope, receive, send)
  File "/opt/anaconda3/envs/webAi/lib/python3.10/site-packages/starlette/routing.py", line 76, in app
    await wrap_app_handling_exceptions(app, request)(scope, receive, send)
  File "/opt/anaconda3/envs/webAi/lib/python3.10/site-packages/starlette/_exception_handler.py", line 53, in wrapped_app
    raise exc
  File "/opt/anaconda3/envs/webAi/lib/python3.10/site-packages/starlette/_exception_handler.py", line 42, in wrapped_app
    await app(scope, receive, sender)
  File "/opt/anaconda3/envs/webAi/lib/python3.10/site-packages/starlette/routing.py", line 73, in app
    response = await f(request)
  File "/opt/anaconda3/envs/webAi/lib/python3.10/site-packages/fastapi/routing.py", line 301, in app
    raw_response = await run_endpoint_function(
  File "/opt/anaconda3/envs/webAi/lib/python3.10/site-packages/fastapi/routing.py", line 212, in run_endpoint_function
    return await dependant.call(**values)
  File "/home/jhyang/AiWeb/webAi_backEnd/app/routers/auth.py", line 83, in login
    result = await db.execute(
  File "/opt/anaconda3/envs/webAi/lib/python3.10/site-packages/sqlalchemy/ext/asyncio/session.py", line 463, in execute
    result = await greenlet_spawn(
  File "/opt/anaconda3/envs/webAi/lib/python3.10/site-packages/sqlalchemy/util/_concurrency_py3k.py", line 201, in greenlet_spawn
    result = context.throw(*sys.exc_info())
  File "/opt/anaconda3/envs/webAi/lib/python3.10/site-packages/sqlalchemy/orm/session.py", line 2365, in execute
    return self._execute_internal(
  File "/opt/anaconda3/envs/webAi/lib/python3.10/site-packages/sqlalchemy/orm/session.py", line 2241, in _execute_internal
    conn = self._connection_for_bind(bind)
  File "/opt/anaconda3/envs/webAi/lib/python3.10/site-packages/sqlalchemy/orm/session.py", line 2110, in _connection_for_bind
    return trans._connection_for_bind(engine, execution_options)
  File "<string>", line 2, in _connection_for_bind
  File "/opt/anaconda3/envs/webAi/lib/python3.10/site-packages/sqlalchemy/orm/state_changes.py", line 139, in _go
    ret_value = fn(self, *arg, **kw)
  File "/opt/anaconda3/envs/webAi/lib/python3.10/site-packages/sqlalchemy/orm/session.py", line 1189, in _connection_for_bind
    conn = bind.connect()
  File "/opt/anaconda3/envs/webAi/lib/python3.10/site-packages/sqlalchemy/engine/base.py", line 3274, in connect
    return self._connection_cls(self)
  File "/opt/anaconda3/envs/webAi/lib/python3.10/site-packages/sqlalchemy/engine/base.py", line 148, in __init__
    Connection._handle_dbapi_exception_noconnection(
  File "/opt/anaconda3/envs/webAi/lib/python3.10/site-packages/sqlalchemy/engine/base.py", line 2439, in _handle_dbapi_exception_noconnection
    raise sqlalchemy_exception.with_traceback(exc_info[2]) from e
  File "/opt/anaconda3/envs/webAi/lib/python3.10/site-packages/sqlalchemy/engine/base.py", line 146, in __init__
    self._dbapi_connection = engine.raw_connection()
  File "/opt/anaconda3/envs/webAi/lib/python3.10/site-packages/sqlalchemy/engine/base.py", line 3298, in raw_connection
    return self.pool.connect()
  File "/opt/anaconda3/envs/webAi/lib/python3.10/site-packages/sqlalchemy/pool/base.py", line 449, in connect
    return _ConnectionFairy._checkout(self)
  File "/opt/anaconda3/envs/webAi/lib/python3.10/site-packages/sqlalchemy/pool/base.py", line 1264, in _checkout
    fairy = _ConnectionRecord.checkout(pool)
  File "/opt/anaconda3/envs/webAi/lib/python3.10/site-packages/sqlalchemy/pool/base.py", line 718, in checkout
    with util.safe_reraise():
  File "/opt/anaconda3/envs/webAi/lib/python3.10/site-packages/sqlalchemy/util/langhelpers.py", line 146, in __exit__
    raise exc_value.with_traceback(exc_tb)
  File "/opt/anaconda3/envs/webAi/lib/python3.10/site-packages/sqlalchemy/pool/base.py", line 716, in checkout
    dbapi_connection = rec.get_connection()
  File "/opt/anaconda3/envs/webAi/lib/python3.10/site-packages/sqlalchemy/pool/base.py", line 838, in get_connection
    self.__connect()
  File "/opt/anaconda3/envs/webAi/lib/python3.10/site-packages/sqlalchemy/pool/base.py", line 901, in __connect
    with util.safe_reraise():
  File "/opt/anaconda3/envs/webAi/lib/python3.10/site-packages/sqlalchemy/util/langhelpers.py", line 146, in __exit__
    raise exc_value.with_traceback(exc_tb)
  File "/opt/anaconda3/envs/webAi/lib/python3.10/site-packages/sqlalchemy/pool/base.py", line 897, in __connect
    self.dbapi_connection = connection = pool._invoke_creator(self)
  File "/opt/anaconda3/envs/webAi/lib/python3.10/site-packages/sqlalchemy/engine/create.py", line 646, in connect
    return dialect.connect(*cargs, **cparams)
  File "/opt/anaconda3/envs/webAi/lib/python3.10/site-packages/sqlalchemy/engine/default.py", line 625, in connect
    return self.loaded_dbapi.connect(*cargs, **cparams)  # type: ignore[no-any-return]  # NOQA: E501
  File "/opt/anaconda3/envs/webAi/lib/python3.10/site-packages/sqlalchemy/dialects/mysql/asyncmy.py", line 286, in connect
    await_only(creator_fn(*arg, **kw)),
  File "/opt/anaconda3/envs/webAi/lib/python3.10/site-packages/sqlalchemy/util/_concurrency_py3k.py", line 132, in await_only
    return current.parent.switch(awaitable)  # type: ignore[no-any-return,attr-defined] # noqa: E501
  File "/opt/anaconda3/envs/webAi/lib/python3.10/site-packages/sqlalchemy/util/_concurrency_py3k.py", line 196, in greenlet_spawn
    value = await result
  File "asyncmy/connection.pyx", line 1345, in _connect
  File "asyncmy/connection.pyx", line 590, in connect
sqlalchemy.exc.OperationalError: (asyncmy.errors.OperationalError) (2003, "Can't connect to MySQL server on 'localhost' ([Errno 111] Connect call failed ('127.0.0.1', 3306))")
(Background on this error at: https://sqlalche.me/e/20/e3q8)
